Workbook

Sheet Scottish Open
A1: Player 1 | B1: Player 2 | C1: Simulator | D1: Pick | E1: % | F1: Win | G1: Loss | H1: Tie | I1: Profit | J1: Course ADV | K1: Line | L1: prompt
A2: Scott | B2: Tom Kim | C2: StatCaddy21 | D2: Tom Kim | E2: 0.526 | K2: -110
A3: Fox | B3: Ayora | C3: StatCaddy21 | D3: Fox | E3: 0.619 | K3: 100 | L3: “Use the saved PGA Monte Carlo matchup code on the file I uploaded. It’s a new tournament, same weights and randomness settings. Save the results to Excel.”
A4: Reed | B4: Penge | C4: StatCaddy21 | D4: Reed | E4: 0.516 | K4: -110
A5: Knapp | B5: Cauley | C5: StatCaddy21 | D5: Cauley | E5: 0.634 | K5: 102 | L5: Run the power rankings by multiplying each raw metric by my listed weights and summing them. Do not standardize the inputs. Convert scores to fair win odds using a softened softmax with temperature 3.0.
A6: Wallace | B6: Hall | C6: StatCaddy21 | D6: Wallace | E6: 0.635 | K6: -108
A7: Cole | B7: Smalley | C7: StatCaddy21 | D7: Cole | E7: 0.509 | K7: -130
A8: Michael Kim | B8: J Svensson | C8: StatCaddy21 | D8: M Kim | E8: 0.569 | K8: -125
A9: Jarvis | B9: Weisberger | C9: StatCaddy21 | D9: Wiesberger | E9: 0.581 | K9: -113
A10: Si Woo Kim | B10: Min Woo Lee | C10: StatCaddy22 | D10: Si Woo | E10: 0.615 | K10: -123
A11: Spaun | B11: Koepka | C11: StatCaddy21 | D11: Spaun | E11: 0.564 | K11: -169
A12: Cantlay | B12: Thomas | C12: StatCaddy21 | D12: Cantlay | E12: 0.52 | K12: 110
A13: N Hojgaard | B13: Reitan | C13: StatCaddy21 | D13: Reitan | E13: 0.597 | K13: 107
A14: Brennan | B14: Thorbjornsen | C14: StatCaddy21 | D14: Brennan | E14: 0.592 | K14: -136
A15: Schauffele | B15: Fleetwood | C15: StatCaddy21 | D15: Fleetwood | E15: 0.524 | K15: -138
A16: Kitayama | B16: English | C16: StatCaddy21 | D16: Kitayama | E16: 0.579 | K16: -113 | N16: `
A17: R Hojgaard | B17: Neergaard Peterson | C17: StatCaddy21 | D17: Neergaard | E17: 0.524 | K17: 110
A18: Rai | B18: Lowry | C18: StatCaddy21 | D18: Rai | E18: 0.546 | K18: 104
A19: Straka | B19: Hillier | C19: StatCaddy21 | D19: Hillier | E19: 0.566 | K19: -120
A20: Gotterup | B20: Clark | C20: StatCaddy21 | D20: Clark | E20: 0.633 | K20: 104
A21: Hatton | B21: MacIntyre | C21: StatCaddy21 | D21: Hatton | E21: 0.672 | K21: -105
A22: Potgieter | B22: Yellamaraju | C22: StatCaddy21 | D22: Potgieter | E22: 0.587 | K22: -117
A23: Aberg | B23: Hovland | C23: StatCaddy21 | D23: Aberg | E23: 0.58 | K23: -149
A24: Chacarra | B24: Noren | C24: StatCaddy21 | D24: Chacarra | E24: 0.588 | K24: -120
A25: McKibbin | B25: Perez | C25: StatCaddy21 | D25: Perez | E25: 0.599 | K25: 113
A26: Yu | B26: Li | C26: StatCaddy21 | D26: Yu | E26: 0.621 | K26: -135
A27: Coody | B27: Gerard | C27: StatCaddy21 | D27: Gerard | E27: 0.544 | K27: -128
A28: Stevens | B28: Keefer | C28: StatCaddy21 | D28: Keefer | E28: 0.506 | K28: 115
... A30: A Fitzpatrick | B30: Puig | C30: StatCaddy21 | D30: Fitzpatrick | E30: 0.678 | K30: -130
C31: StatCaddy22
C32: StatCaddy21
C33: StatCaddy21
C34: StatCaddy21
C35: StatCaddy21
C36: StatCaddy21
C37: StatCaddy21
C38: StatCaddy21
C39: StatCaddy21
C40: StatCaddy21
C41: StatCaddy21
...

Sheet YTD StatCaddy18
A1: SIM - Altered Stat Weights
B2: OVERALL | F2: Win % | H2: Green Lights | L2: Win % | N2: 57% + Course Fit or History | R2: Win % | T2: vs Data Golf | W2: Win %
A3: 2025 | B3: W | C3: L | D3: T | E3: $ | F3: % | G3: 2025 | H3: W | I3: L | J3: T | L3: % | M3: 2025 | N3: W | O3: L | P3: T | Q3: $ | R3: % | S3: 2025 | T3: W | U3: L | V3: T | W3: %
A4: World Wide Technology | B4: 30 | C4: 17 | D4: 0 | E4: 944 | F4: =B4/(B4+C4) -> 0.63829787 | G4: World Wide Technology | L4: =H4/(H4+I4) -> #DIV/0! | M4: World Wide Technology | N4: 7 | O4: 5 | P4: 0 | Q4: 134 | R4: =N4/(N4+O4) -> 0.58333333 | S4: World Wide Technology | T4: 5 | U4: 4 | V4: 0 | W4: =T4/(T4+U4) -> 0.55555556
A5: Butterfield Bermuda | B5: 23 | C5: 20 | D5: 2 | E5: -13 | F5: =B5/(B5+C5) -> 0.53488372 | G5: Butterfield Bermuda | L5: =H5/(H5+I5) -> #DIV/0! | M5: Butterfield Bermuda | N5: 6 | O5: 5 | P5: 0 | Q5: -49 | R5: =N5/(N5+O5) -> 0.54545455 | S5: Butterfield Bermuda | T5: 11 | U5: 8 | V5: 0 | W5: =T5/(T5+U5) -> 0.57894737
A6: RSM Classic | B6: 21 | C6: 20 | D6: 4 | E6: -89 | F6: =B6/(B6+C6) -> 0.51219512 | G6: RSM Classic | H6: 5 | I6: 0 | J6: 0 | K6: 500 | L6: =H6/(H6+I6) -> 1 | M6: RSM Classic | N6: 7 | O6: 3 | P6: 2 | Q6: 356 | R6: =N6/(N6+O6) -> 0.7 | S6: RSM Classic | T6: 5 | U6: 6 | V6: 1 | W6: =T6/(T6+U6) -> 0.45454545
A7: Hero World Challenge | B7: 16 | C7: 23 | D7: 1 | E7: -1208 | F7: =B7/(B7+C7) -> 0.41025641 | G7: Hero World Challenge | H7: 1 | I7: 3 | J7: 1 | K7: -229 | L7: =H7/(H7+I7) -> 0.25 | M7: Hero World Challenge | N7: 2 | O7: 4 | P7: 1 | Q7: -216 | R7: =N7/(N7+O7) -> 0.33333333 | S7: Hero World Challenge | T7: 6 | U7: 6 | V7: 1 | W7: =T7/(T7+U7) -> 0.5
A8: Wyndham Champ. | F8: =B8/(B8+C8) -> #DIV/0! | G8: Wyndham Champ. | L8: =H8/(H8+I8) -> #DIV/0! | M8: Wyndham Champ. | R8: =N8/(N8+O8) -> #DIV/0! | S8: Wyndham Champ. | W8: =T8/(T8+U8) -> #DIV/0!
A9: BMW Champ. | F9: =B9/(B9+C9) -> #DIV/0! | G9: BMW Champ. | L9: =H9/(H9+I9) -> #DIV/0! | M9: BMW Champ. | R9: =N9/(N9+O9) -> #DIV/0! | S9: BMW Champ. | W9: =T9/(T9+U9) -> #DIV/0!
A10: Tour Champ. | F10: =B10/(B10+C10) -> #DIV/0! | G10: Tour Champ. | L10: =H10/(H10+I10) -> #DIV/0! | M10: Tour Champ. | R10: =N10/(N10+O10) -> #DIV/0! | S10: Tour Champ. | W10: =T10/(T10+U10) -> #DIV/0!
A11: 2025 Year End | B11: =SUM(B4:B10) -> 90 | C11: =SUM(C4:C10) -> 80 | D11: =SUM(D4:D10) -> 7 | E11: =SUM(E4:E7) -> -366 | F11: =B11/(B11+C11) -> 0.52941176 | G11: 2025 Year End | H11: =SUM(H4:H10) -> 6 | I11: =SUM(I4:I10) -> 3 | J11: =SUM(J4:J10) -> 1 | K11: =SUM(K4:K7) -> 271 | L11: =H11/(H11+I11) -> 0.66666667 | M11: 2025 Year End | N11: =SUM(N4:N10) -> 22 | O11: =SUM(O4:O10) -> 17 | P11: =SUM(P4:P10) -> 3 | Q11: =SUM(Q4:Q7) -> 225 | R11: =N11/(N11+O11) -> 0.56410256 | S11: 2025 Year End | T11: =SUM(T4:T10) -> 27 | U11: =SUM(U4:U10) -> 24 | V11: =SUM(V4:V10) -> 2 | W11: =T11/(T11+U11) -> 0.52941176
A12: 2026 | B12: W | C12: L | D12: T | E12: $ | F12: % | G12: 2026 | H12: W | I12: L | J12: T | K12: $ | L12: % | M12: 2026 | N12: W | O12: L | P12: T | Q12: $ | R12: % | S12: 2026 | T12: W | U12: L | V12: T | W12: %
A13: Sony Open | B13: 23 | C13: 22 | D13: 3 | E13: -295 | F13: =B13/(B13+C13) -> 0.51111111 | G13: Sony Open | H13: 3 | I13: 1 | J13: 1 | K13: 190 | L13: =H13/(H13+I13) -> 0.75 | M13: Sony Open | R13: =N13/(N13+O13) -> #DIV/0! | S13: Sony Open | T13: 6 | U13: 11 | V13: 2 | W13: =T13/(T13+U13) -> 0.35294118
A14: American Express | B14: 32 | C14: 27 | D14: 2 | E14: 36 | F14: =B14/(B14+C14) -> 0.54237288 | G14: American Express | H14: 2 | I14: 3 | J14: 0 | K14: -80 | L14: =H14/(H14+I14) -> 0.4 | M14: American Express | R14: =N14/(N14+O14) -> #DIV/0! | S14: American Express | T14: 9 | U14: 18 | V14: 2 | W14: =T14/(T14+U14) -> 0.33333333 | X14: Must add other 2 courses
A15: Farmers Insurance | B15: 25 | C15: 27 | D15: 2 | E15: -675 | F15: =B15/(B15+C15) -> 0.48076923 | G15: Farmers Insurance | H15: 0 | I15: 5 | J15: 0 | K15: -612 | L15: =H15/(H15+I15) -> 0 | M15: Farmers Insurance | R15: =N15/(N15+O15) -> #DIV/0! | S15: Farmers Insurance | T15: 6 | U15: 11 | V15: 0 | W15: =T15/(T15+U15) -> 0.35294118
A16: WM Phoenix Open | B16: 29 | C16: 27 | D16: 1 | E16: -180 | F16: =B16/(B16+C16) -> 0.51785714 | G16: WM Phoenix Open | H16: 3 | I16: 2 | J16: 0 | K16: 75 | L16: =H16/(H16+I16) -> 0.6 | M16: WM Phoenix Open | R16: =N16/(N16+O16) -> #DIV/0! | S16: WM Phoenix Open | T16: 10 | U16: 13 | V16: 1 | W16: =T16/(T16+U16) -> 0.43478261
A17: AT&T Pebble Beach | B17: 20 | C17: 6 | D17: 2 | E17: 1333 | F17: =B17/(B17+C17) -> 0.76923077 | G17: AT&T Pebble Beach | H17: 2 | I17: 3 | J17: 0 | K17: -147 | L17: =H17/(H17+I17) -> 0.4 | M17: AT&T Pebble Beach | R17: =N17/(N17+O17) -> #DIV/0! | S17: AT&T Pebble Beach | T17: 8 | U17: 3 | V17: 1 | W17: =T17/(T17+U17) -> 0.72727273
A18: Genesis Invitational | B18: 22 | C18: 38 | D18: 2 | E18: -1855 | F18: =B18/(B18+C18) -> 0.36666667 | G18: Genesis Invitational | H18: 1 | I18: 4 | J18: 0 | K18: -354 | L18: =H18/(H18+I18) -> 0.2 | M18: Genesis Invitational | R18: =N18/(N18+O18) -> #DIV/0! | S18: Genesis Invitational | T18: 5 | U18: 18 | V18: 1 | W18: =T18/(T18+U18) -> 0.2173913
A19: Cognizant Classic | B19: 14 | C19: 13 | D19: 0 | E19: 56 | F19: =B19/(B19+C19) -> 0.51851852 | G19: Cognizant Classic | H19: 3 | I19: 2 | J19: 0 | K19: 123 | L19: =H19/(H19+I19) -> 0.6 | M19: Cognizant Classic | R19: =N19/(N19+O19) -> #DIV/0! | S19: Cognizant Classic | T19: 4 | U19: 4 | V19: 0 | W19: =T19/(T19+U19) -> 0.5
A20: Arnold Palmer Invitational | B20: 18 | C20: 12 | D20: 0 | E20: 501 | F20: =B20/(B20+C20) -> 0.6 | G20: Arnold Palmer Invitational | H20: 4 | I20: 0 | J20: 0 | K20: 459 | L20: =H20/(H20+I20) -> 1 | M20: Arnold Palmer Invitational | R20: =N20/(N20+O20) -> #DIV/0! | S20: Arnold Palmer Invitational | T20: 8 | U20: 3 | V20: 0 | W20: =T20/(T20+U20) -> 0.72727273 | X20: 5X course fit
A21: The Players Championship | B21: 16 | C21: 15 | D21: 5 | E21: -347 | F21: =B21/(B21+C21) -> 0.51612903 | G21: The Players Championship | H21: 1 | I21: 3 | J21: 1 | K21: -185 | L21: =H21/(H21+I21) -> 0.25 | M21: The Players Championship | R21: =N21/(N21+O21) -> #DIV/0! | S21: The Players Championship | T21: 5 | U21: 5 | V21: 0 | W21: =T21/(T21+U21) -> 0.5
A22: Valspar Championship | B22: 21 | C22: 13 | D22: 0 | E22: 636 | F22: =B22/(B22+C22) -> 0.61764706 | G22: Valspar Championship | H22: 2 | I22: 3 | J22: 0 | K22: -123 | L22: =H22/(H22+I22) -> 0.4 | M22: Valspar Championship | R22: =N22/(N22+O22) -> #DIV/0! | S22: Valspar Championship | T22: 9 | U22: 7 | V22: 0 | W22: =T22/(T22+U22) -> 0.5625
A23: Texas Childrens Houston Open | B23: 27 | C23: 22 | D23: 4 | E23: 254 | F23: =B23/(B23+C23) -> 0.55102041 | G23: Texas Childrens Houston Open | H23: 9 | I23: 6 | J23: 0 | K23: 298 | L23: =H23/(H23+I23) -> 0.6 | M23: Texas Childrens Houston Open | N23: 8 | O23: 1 | P23: 0 | Q23: 699 | R23: =N23/(N23+O23) -> 0.88888889 | S23: Texas Childrens Houston Open | T23: 9 | U23: 12 | V23: 3 | W23: =T23/(T23+U23) -> 0.42857143 | X23: Start of current weights
A24: Valero Texas Open | B24: 18 | C24: 29 | D24: 2 | E24: -1599 | F24: =B24/(B24+C24) -> 0.38297872 | G24: Valero Texas Open | H24: 4 | I24: 4 | J24: 0 | K24: -51 | L24: =H24/(H24+I24) -> 0.5 | M24: Valero Texas Open | N24: 3 | O24: 6 | P24: 0 | Q24: -435 | R24: =N24/(N24+O24) -> 0.33333333 | S24: Valero Texas Open | T24: 7 | U24: 11 | V24: 0 | W24: =T24/(T24+U24) -> 0.38888889 | X24: Horrible weather
A25: Masters | B25: 22 | C25: 22 | D25: 4 | E25: -391 | F25: =B25/(B25+C25) -> 0.5 | G25: Masters | H25: 5 | I25: 3 | J25: 1 | K25: 380 | L25: =H25/(H25+I25) -> 0.625 | M25: Masters | N25: 5 | O25: 1 | P25: 1 | Q25: 380 | R25: =N25/(N25+O25) -> 0.83333333 | S25: Masters | T25: 8 | U25: 7 | V25: 2 | W25: =T25/(T25+U25) -> 0.53333333 | X25: Course History
A26: RBC Heritage | F26: =B26/(B26+C26) -> #DIV/0! | G26: RBC Heritage | L26: =H26/(H26+I26) -> #DIV/0! | M26: RBC Heritage | R26: =N26/(N26+O26) -> #DIV/0! | S26: RBC Heritage | W26: =T26/(T26+U26) -> #DIV/0!
A27: Miami Championship | F27: =B27/(B27+C27) -> #DIV/0! | G27: Miami Championship | L27: =H27/(H27+I27) -> #DIV/0! | M27: Miami Championship | R27: =N27/(N27+O27) -> #DIV/0! | S27: Miami Championship | W27: =T27/(T27+U27) -> #DIV/0!
A28: Truist Championship | F28: =B28/(B28+C28) -> #DIV/0! | G28: Truist Championship | L28: =H28/(H28+I28) -> #DIV/0! | M28: Truist Championship | R28: =N28/(N28+O28) -> #DIV/0! | S28: Truist Championship | W28: =T28/(T28+U28) -> #DIV/0!
A29: Myrtle Beach Classic | F29: =B29/(B29+C29) -> #DIV/0! | G29: Myrtle Beach Classic | L29: =H29/(H29+I29) -> #DIV/0! | M29: Myrtle Beach Classic | R29: =N29/(N29+O29) -> #DIV/0! | S29: Myrtle Beach Classic | W29: =T29/(T29+U29) -> #DIV/0!
A30: PGA Championship | F30: =B30/(B30+C30) -> #DIV/0! | G30: PGA Championship | L30: =H30/(H30+I30) -> #DIV/0! | M30: PGA Championship | R30: =N30/(N30+O30) -> #DIV/0! | S30: PGA Championship | W30: =T30/(T30+U30) -> #DIV/0!
A31: Charles Schwab Challenge | F31: =B31/(B31+C31) -> #DIV/0! | G31: Charles Schwab Challenge | L31: =H31/(H31+I31) -> #DIV/0! | M31: Charles Schwab Challenge | R31: =N31/(N31+O31) -> #DIV/0! | S31: Charles Schwab Challenge | W31: =T31/(T31+U31) -> #DIV/0!
A32: Memorial Tournament | F32: =B32/(B32+C32) -> #DIV/0! | G32: Memorial Tournament | L32: =H32/(H32+I32) -> #DIV/0! | M32: Memorial Tournament | R32: =N32/(N32+O32) -> #DIV/0! | S32: Memorial Tournament | W32: =T32/(T32+U32) -> #DIV/0!
A33: RBC Canadian Open | F33: =B33/(B33+C33) -> #DIV/0! | G33: RBC Canadian Open | L33: =H33/(H33+I33) -> #DIV/0! | M33: RBC Canadian Open | R33: =N33/(N33+O33) -> #DIV/0! | S33: RBC Canadian Open | W33: =T33/(T33+U33) -> #DIV/0!
A34: U.S. Open | F34: =B34/(B34+C34) -> #DIV/0! | G34: U.S. Open | L34: =H34/(H34+I34) -> #DIV/0! | M34: U.S. Open | R34: =N34/(N34+O34) -> #DIV/0! | S34: U.S. Open | W34: =T34/(T34+U34) -> #DIV/0!
A35: Travelers Championship | F35: =B35/(B35+C35) -> #DIV/0! | G35: Travelers Championship | L35: =H35/(H35+I35) -> #DIV/0! | M35: Travelers Championship | R35: =N35/(N35+O35) -> #DIV/0! | S35: Travelers Championship | W35: =T35/(T35+U35) -> #DIV/0!
A36: John Deere Classic | F36: =B36/(B36+C36) -> #DIV/0! | G36: John Deere Classic | L36: =H36/(H36+I36) -> #DIV/0! | M36: John Deere Classic | R36: =N36/(N36+O36) -> #DIV/0! | S36: John Deere Classic | W36: =T36/(T36+U36) -> #DIV/0!
A37: Genesis Scottish Open | F37: =B37/(B37+C37) -> #DIV/0! | G37: Genesis Scottish Open | L37: =H37/(H37+I37) -> #DIV/0! | M37: Genesis Scottish Open | R37: =N37/(N37+O37) -> #DIV/0! | S37: Genesis Scottish Open | W37: =T37/(T37+U37) -> #DIV/0!
... A46: Tour Championship | F46: =B46/(B46+C46) -> #DIV/0! | G46: Tour Championship | L46: =H46/(H46+I46) -> #DIV/0! | M46: Tour Championship | R46: =N46/(N46+O46) -> #DIV/0! | S46: Tour Championship | W46: =T46/(T46+U46) -> #DIV/0!
A47: 2026 | B47: W | C47: L | D47: T | E47: $ | F47: % | G47: 2026 | H47: W | I47: L | J47: T | K47: $ | L47: % | M47: 2026 | N47: W | O47: L | P47: T | Q47: $ | R47: % | S47: 2026 | T47: W | U47: L | V47: T | W47: %
A48: YTD | B48: =SUM(B13:B46) -> 287 | C48: =SUM(C13:C46) -> 273 | D48: =SUM(D13:D46) -> 27 | E48: =SUM(E13:E46) -> -2526 | F48: =B48/(B48+C48) -> 0.5125 | G48: YTD | H48: =SUM(H13:H46) -> 39 | I48: =SUM(I13:I46) -> 39 | J48: =SUM(J13:J46) -> 3 | K48: =SUM(K13:K46) -> -27 | L48: =H48/(H48+I48) -> 0.5 | M48: YTD | N48: =SUM(N13:N46) -> 16 | O48: =SUM(O13:O46) -> 8 | P48: =SUM(P13:P46) -> 1 | Q48: =SUM(Q13:Q46) -> 644 | R48: =N48/(N48+O48) -> 0.66666667 | S48: YTD | T48: =SUM(T13:T46) -> 94 | U48: =SUM(U13:U46) -> 123 | V48: =SUM(V13:V46) -> 12 | W48: =T48/(T48+U48) -> 0.43317972
...

Sheet Class
A1: LAST 10 | B1: 46159 | C1: 46166 | D1: 46173 | E1: 46180 | F1: 46187 | G1: 46194 | H1: 46201 | I1: 46208 | J1: 46215 | K1: 46222 | L1: 46229 | M1: 46236 | N1: 46243 | O1: 46250 | P1: 46257 | Q1: DG POINTS | S1: Weighted | T1: 0.25
A2: Ludvig Aberg | B2: 6.41 | D2: 0.78 | E2: 0.25 | G2: 1.68 | H2: 0 | J2: 0 | K2: 2.96 | O2: 2.2 | P2: 0.69 | Q2: =TRIMMEAN(B2:P2,2/COUNT(B2:P2)) -> 1.2228571
A3: Marcus Armitage | C3: 1.33 | D3: 0.2 | E3: 0.36 | H3: 0 | I3: 0.03 | J3: 0.73 | Q3: =TRIMMEAN(B3:P3,2/COUNT(B3:P3)) -> 0.33
A4: Angel Ayora | B4: 0 | E4: 1.18 | H4: 1.24 | I4: 0 | J4: 0 | K4: 0 | Q4: =TRIMMEAN(B4:P4,2/COUNT(B4:P4)) -> 0.295
A5: Zach Bauchou | C5: 1.53 | D5: 0.59 | F5: 0 | I5: 0 | J5: 0 | K5: 0.68 | L5: 0.24 | M5: 0 | N5: 0.99 | Q5: =TRIMMEAN(B5:P5,2/COUNT(B5:P5)) -> 0.35714286
A6: Christiaan Bezuidenhout | B6: 0.74 | C6: 0 | D6: 0.42 | F6: 0 | I6: 0.93 | J6: 0.3 | K6: 0 | L6: 0.59 | M6: 0.31 | N6: 0.34 | Q6: =TRIMMEAN(B6:P6,2/COUNT(B6:P6)) -> 0.3375
A7: Daniel Berger | B7: 0.74 | E7: 0 | G7: 0 | H7: 0.52 | I7: 0 | K7: 0 | Q7: =TRIMMEAN(B7:P7,2/COUNT(B7:P7)) -> 0.13
A8: Akshay Bhatia | B8: 0 | D8: 0.48 | E8: 0 | G8: 1.68 | H8: 3.46 | K8: 0 | M8: 0 | O8: 0 | P8: 1.09 | Q8: =TRIMMEAN(B8:P8,2/COUNT(B8:P8)) -> 0.46428571
A9: Zac Blair | C9: 0 | D9: 0 | G9: 0.84 | I9: 1.18 | J9: 0.84 | L9: 0.9 | M9: 0.03 | N9: 0 | Q9: =TRIMMEAN(B9:P9,2/COUNT(B9:P9)) -> 0.435
A10: Chandler Blanchet | B10: 0.38 | C10: 0 | D10: 0.21 | F10: 0 | I10: 0 | J10: 0 | K10: 0 | L10: 0.46 | M10: 0.75 | N10: 0 | Q10: =TRIMMEAN(B10:P10,2/COUNT(B10:P10)) -> 0.13125
A11: Dan Bradbury | E11: 0 | H11: 0.16 | I11: 0 | J11: 0 | K11: 0 | Q11: =TRIMMEAN(B11:P11,2/COUNT(B11:P11)) -> 0
A12: Keegan Bradley | B12: 0 | D12: 0.35 | E12: 0.82 | G12: 0.84 | H12: 0.98 | I12: 0.42 | K12: 0 | M12: 1.01 | N12: 0.11 | Q12: =TRIMMEAN(B12:P12,2/COUNT(B12:P12)) -> 0.50285714
A13: Michael Brennan | B13: 0 | C13: 0 | D13: 1.91 | F13: 0 | G13: 0.48 | I13: 0.33 | J13: 0 | K13: 0 | L13: 0.46 | M13: 1.01 | N13: 10.11 | O13: 0.17 | P13: 1.51 | Q13: =TRIMMEAN(B13:P13,2/COUNT(B13:P13)) -> 0.53363636
A14: Jacob Bridgeman | B14: 0 | E14: 0.33 | F14: 1.21 | G14: 0.71 | H14: 0.13 | I14: 0.42 | K14: 0.89 | M14: 0.59 | O14: 0.39 | P14: 1.81 | Q14: =TRIMMEAN(B14:P14,2/COUNT(B14:P14)) -> 0.58375
A15: Blades Brown | C15: 0.75 | I15: 0.93 | K15: 0.53 | N15: 0 | Q15: =TRIMMEAN(B15:P15,2/COUNT(B15:P15)) -> 0.64
A16: Dan Brown | B16: 0 | C16: 0.12 | D16: 0 | F16: 0 | J16: 0 | K16: 1.41 | Q16: =TRIMMEAN(B16:P16,2/COUNT(B16:P16)) -> 0.03
A17: Hayden Buckley | Q17: =TRIMMEAN(B17:P17,2/COUNT(B17:P17)) -> #DIV/0!
A18: Bronson Burgoon | Q18: =TRIMMEAN(B18:P18,2/COUNT(B18:P18)) -> #DIV/0!
A19: Sam Burns | B19: 1.01 | E19: 4.28 | F19: 0.62 | G19: 14.7 | H19: 1.46 | K19: 10.11 | O19: 5.56 | P19: 0.25 | Q19: =TRIMMEAN(B19:P19,2/COUNT(B19:P19)) -> 3.84
A20: Brian Campbell | B20: 0 | D20: 0 | E20: 0 | F20: 0 | H20: 0.13 | I20: 0 | J20: 0 | L20: 0 | M20: 0 | N20: 0 | Q20: =TRIMMEAN(B20:P20,2/COUNT(B20:P20)) -> 0
A21: Rafael Campos | C21: 0 | F21: 0 | I21: 0 | J21: 0.43 | K21: 0 | L21: 0 | M21: 0 | N21: 0.59 | Q21: =TRIMMEAN(B21:P21,2/COUNT(B21:P21)) -> 0.071666667
A22: Laurie Canter | D22: 0.32 | E22: 0.03 | G22: 0.48 | J22: 0.18 | K22: 0 | Q22: =TRIMMEAN(B22:P22,2/COUNT(B22:P22)) -> 0.17666667
A23: Patrick Cantlay | B23: 0.74 | E23: 0.98 | G23: 0 | H23: 0.98 | J23: 0 | K23: 0.89 | M23: 1.56 | O23: 1.22 | P23: 8.61 | Q23: =TRIMMEAN(B23:P23,2/COUNT(B23:P23)) -> 0.91
A24: Frankie Capan III | Q24: =TRIMMEAN(B24:P24,2/COUNT(B24:P24)) -> #DIV/0!
A25: Ricky Castillo | B25: 0 | D25: 0.21 | F25: 0.27 | J25: 0.39 | L25: 0.24 | M25: 0.75 | N25: 0.11 | O25: 0 | Q25: =TRIMMEAN(B25:P25,2/COUNT(B25:P25)) -> 0.20333333
A26: Bud Cauley | B26: 1.01 | E26: 0.63 | F26: 10.5 | G26: 0 | H26: 0.98 | J26: 0 | K26: 1.41 | N26: 0 | O26: 1.22 | P26: 0.03 | Q26: =TRIMMEAN(B26:P26,2/COUNT(B26:P26)) -> 0.66
A27: Eugenio Chacarra | C27: 0.28 | D27: 0.43 | E27: 3.55 | H27: 4.33 | I27: 0 | J27: 0 | K27: 0.41 | Q27: =TRIMMEAN(B27:P27,2/COUNT(B27:P27)) -> 0.934
A28: Cameron Champ | C28: 0 | I28: 0 | J28: 0.16 | K28: 0 | L28: 0 | Q28: =TRIMMEAN(B28:P28,2/COUNT(B28:P28)) -> 0
A29: Will Chandler | Q29: =TRIMMEAN(B29:P29,2/COUNT(B29:P29)) -> #DIV/0!
A30: Davis Chatfield | C30: 0 | D30: 0 | F30: 0 | I30: 0.33 | J30: 1.13 | K30: 0.17 | L30: 0.73 | M30: 0 | N30: 0.59 | Q30: =TRIMMEAN(B30:P30,2/COUNT(B30:P30)) -> 0.26
A31: Luke Clanton | C31: 0.32 | D31: 0 | F31: 0 | I31: 0 | J31: 0 | K31: 0 | L31: 0 | M31: 0.75 | N31: 0 | Q31: =TRIMMEAN(B31:P31,2/COUNT(B31:P31)) -> 0.045714286
A32: Wyndham Clark | B32: 0 | C32: 7.92 | E32: 6.23 | F32: 1.21 | G32: 28 | H32: 3.46 | J32: 1.47 | K32: 0 | M32: 0 | O32: 3.53 | P32: 17.15 | Q32: =TRIMMEAN(B32:P32,2/COUNT(B32:P32)) -> 4.5522222
A33: Eric Cole | C33: 0.32 | D33: 5.56 | E33: 2.39 | F33: 0 | H33: 0.22 | I33: 0.27 | J33: 0 | K33: 0 | M33: 0 | N33: 0.47 | O33: 0 | P33: 0.25 | Q33: =TRIMMEAN(B33:P33,2/COUNT(B33:P33)) -> 0.392
A34: Trevor Cone | Q34: =TRIMMEAN(B34:P34,2/COUNT(B34:P34)) -> #DIV/0!
A35: Corey Conners | B35: 0 | E35: 0 | F35: 0 | G35: 1.14 | H35: 2.38 | J35: 0 | K35: 2.08 | L35: 0.28 | M35: 0.75 | O35: 0.1 | Q35: =TRIMMEAN(B35:P35,2/COUNT(B35:P35)) -> 0.54375
A36: Pierceson Coody | B36: 0 | C36: 0.47 | D36: 0.59 | E36: 0 | G36: 1.14 | I36: 0.27 | J36: 0 | K36: 0.89 | L36: 0 | M36: 0 | N36: 0 | O36: 0.77 | Q36: =TRIMMEAN(B36:P36,2/COUNT(B36:P36)) -> 0.299
A37: Austin Cook | C37: 0 | J37: 0 | K37: 0.03 | Q37: =TRIMMEAN(B37:P37,2/COUNT(B37:P37)) -> 0
A38: Martin Couvra | C38: 0.24 | D38: 0.15 | E38: 0 | H38: 0 | I38: 0 | J38: 0 | K38: 0 | Q38: =TRIMMEAN(B38:P38,2/COUNT(B38:P38)) -> 0.03
A39: Quade Cummins | Q39: =TRIMMEAN(B39:P39,2/COUNT(B39:P39)) -> #DIV/0!
A40: Joel Dahmen | C40: 0 | D40: 0.21 | F40: 0 | I40: 0.23 | J40: 0.23 | K40: 0.25 | L40: 0.33 | M40: 0 | N40: 0.34 | Q40: =TRIMMEAN(B40:P40,2/COUNT(B40:P40)) -> 0.17857143
...

Sheet SG PUTT
A1: LAST 10 | B1: 46159 | C1: 46166 | D1: 46173 | E1: 46180 | F1: 46187 | G1: 46194 | H1: 46201 | I1: 46208 | J1: 46215 | K1: 46222 | L1: 46229 | M1: 46236 | N1: 46243 | O1: 46250 | P1: 46257 | Q1: SG PUTT | S1: Weighted | T1: 1
A2: Ludvig Aberg | B2: -0.2 | D2: 0.69 | E2: 0.79 | G2: 0.39 | H2: -1 | J2: -0.5 | K2: 0.05 | O2: -0.11 | P2: 1.07 | Q2: =TRIMMEAN(B2:P2,2/COUNT(B2:P2)) -> 0.15857143
A3: Marcus Armitage | C3: 1.24 | D3: 1.66 | E3: 1.29 | H3: -0.63 | I3: -0.42 | J3: 1.32 | Q3: =TRIMMEAN(B3:P3,2/COUNT(B3:P3)) -> 0.8575
A4: Angel Ayora | B4: -1.62 | E4: 1.52 | H4: 0.53 | I4: -1.7 | J4: -1.23 | K4: -1.38 | Q4: =TRIMMEAN(B4:P4,2/COUNT(B4:P4)) -> -0.925
A5: Zach Bauchou | C5: 0.52 | D5: -0.55 | F5: -0.17 | I5: -1.23 | J5: 0.25 | K5: 1.17 | L5: 1.47 | M5: -0.86 | N5: 1.91 | Q5: =TRIMMEAN(B5:P5,2/COUNT(B5:P5)) -> 0.26142857
A6: Christiaan Bezuidenhout | B6: 1.48 | C6: 0.88 | D6: -0.55 | F6: -0.98 | I6: 1.01 | J6: -0.4 | K6: 0.6 | L6: 0.95 | M6: 0.24 | N6: 0.71 | Q6: =TRIMMEAN(B6:P6,2/COUNT(B6:P6)) -> 0.43
A7: Daniel Berger | B7: 0.72 | E7: -1.2 | G7: -2.09 | H7: -0.71 | I7: -0.86 | K7: -1.55 | Q7: =TRIMMEAN(B7:P7,2/COUNT(B7:P7)) -> -1.08
A8: Akshay Bhatia | B8: 0.49 | D8: 0.96 | E8: -0.76 | G8: 0.52 | H8: 1.43 | K8: -0.25 | M8: 0.23 | O8: -1.3 | P8: 0.21 | Q8: =TRIMMEAN(B8:P8,2/COUNT(B8:P8)) -> 0.2
A9: Zac Blair | C9: -0.8 | D9: -0.57 | G9: 1.06 | I9: 1.26 | J9: 0.54 | L9: 1.8 | M9: -0.1 | N9: 0.24 | Q9: =TRIMMEAN(B9:P9,2/COUNT(B9:P9)) -> 0.405
A10: Chandler Blanchet | B10: 0.47 | C10: -1.43 | D10: -0.18 | F10: -0.18 | I10: -1.76 | J10: -2.05 | K10: 0.63 | L10: -0.05 | M10: 0.92 | N10: -1.79 | Q10: =TRIMMEAN(B10:P10,2/COUNT(B10:P10)) -> -0.53625
A11: Dan Bradbury | E11: -1.68 | H11: -0.8 | I11: -1.18 | J11: -0.5 | K11: -1.78 | Q11: =TRIMMEAN(B11:P11,2/COUNT(B11:P11)) -> -1.22
A12: Keegan Bradley | B12: -0.74 | D12: 0.49 | E12: 0.27 | G12: -0.66 | H12: -0.38 | I12: 0.35 | K12: -1.05 | M12: 0.19 | N12: -0.82 | Q12: =TRIMMEAN(B12:P12,2/COUNT(B12:P12)) -> -0.25571429
A13: Michael Brennan | B13: -1.2 | C13: -0.43 | D13: 1.4 | F13: -0.67 | G13: -0.62 | I13: -0.22 | J13: -1.18 | K13: -0.49 | L13: 0.59 | M13: 1.87 | N13: 2.24 | O13: 0.42 | P13: 0.45 | Q13: =TRIMMEAN(B13:P13,2/COUNT(B13:P13)) -> 0.10181818
A14: Jacob Bridgeman | B14: -1.3 | E14: -0.37 | F14: 0.84 | G14: 1.15 | H14: -0.38 | I14: 0.63 | K14: 0.52 | M14: 0.82 | O14: 1.34 | P14: 0.42 | Q14: =TRIMMEAN(B14:P14,2/COUNT(B14:P14)) -> 0.45375
A15: Blades Brown | C15: 0.27 | I15: 0.58 | K15: 0.22 | N15: -2.73 | Q15: =TRIMMEAN(B15:P15,2/COUNT(B15:P15)) -> 0.245
A16: Dan Brown | B16: 0.09 | C16: -0.61 | D16: -1.77 | F16: -1.35 | J16: -2.91 | K16: 0.57 | Q16: =TRIMMEAN(B16:P16,2/COUNT(B16:P16)) -> -0.91
A17: Hayden Buckley | Q17: =TRIMMEAN(B17:P17,2/COUNT(B17:P17)) -> #DIV/0!
A18: Bronson Burgoon | Q18: =TRIMMEAN(B18:P18,2/COUNT(B18:P18)) -> #DIV/0!
A19: Sam Burns | B19: 1.04 | E19: 1.28 | F19: 0.01 | G19: 1.1 | H19: 0.51 | K19: 0.69 | O19: 1.15 | P19: -0.31 | Q19: =TRIMMEAN(B19:P19,2/COUNT(B19:P19)) -> 0.75
A20: Brian Campbell | B20: -0.11 | D20: -2.01 | E20: -0.11 | F20: -0.71 | H20: 0.63 | I20: -0.17 | J20: -1.87 | L20: -0.59 | M20: -0.98 | N20: -1.34 | Q20: =TRIMMEAN(B20:P20,2/COUNT(B20:P20)) -> -0.735
A21: Rafael Campos | C21: -0.09 | F21: -1.84 | I21: -0.91 | J21: 1.5 | K21: 0.09 | L21: -1.09 | M21: -2.87 | N21: 0.62 | Q21: =TRIMMEAN(B21:P21,2/COUNT(B21:P21)) -> -0.53666667
A22: Laurie Canter | D22: -0.73 | E22: -0.46 | G22: 0.29 | J22: -0.78 | K22: 0.32 | Q22: =TRIMMEAN(B22:P22,2/COUNT(B22:P22)) -> -0.3
A23: Patrick Cantlay | B23: -0.27 | E23: 0.41 | G23: -1.07 | H23: 0.41 | J23: 0.43 | K23: 0.61 | M23: 0.47 | O23: -0.24 | P23: -0.94 | Q23: =TRIMMEAN(B23:P23,2/COUNT(B23:P23)) -> 0.038571429
A24: Frankie Capan III | Q24: =TRIMMEAN(B24:P24,2/COUNT(B24:P24)) -> #DIV/0!
A25: Ricky Castillo | B25: 0.02 | D25: -0.75 | F25: -0.05 | J25: 0.41 | L25: 1 | M25: 0.77 | N25: -1.12 | O25: 0.27 | Q25: =TRIMMEAN(B25:P25,2/COUNT(B25:P25)) -> 0.11166667
A26: Bud Cauley | B26: 0.96 | E26: 0.41 | F26: 1.69 | G26: -1.03 | H26: -0.65 | J26: -2.69 | K26: 1.57 | N26: -0.4 | O26: -0.25 | P26: -0.14 | Q26: =TRIMMEAN(B26:P26,2/COUNT(B26:P26)) -> 0.05875
A27: Eugenio Chacarra | C27: 0.84 | D27: -0.19 | E27: -0.07 | H27: 1.64 | I27: 0.38 | J27: -1.05 | K27: 0.71 | Q27: =TRIMMEAN(B27:P27,2/COUNT(B27:P27)) -> 0.334
A28: Cameron Champ | C28: -0.19 | I28: -0.29 | J28: 0.25 | K28: 0.7 | L28: -0.59 | Q28: =TRIMMEAN(B28:P28,2/COUNT(B28:P28)) -> -0.076666667
A29: Will Chandler | Q29: =TRIMMEAN(B29:P29,2/COUNT(B29:P29)) -> #DIV/0!
A30: Davis Chatfield | C30: -0.17 | D30: 1.35 | F30: -0.25 | I30: -0.28 | J30: 1.55 | K30: 0.87 | L30: 0.98 | M30: -0.57 | N30: -0.15 | Q30: =TRIMMEAN(B30:P30,2/COUNT(B30:P30)) -> 0.33571429
A31: Luke Clanton | C31: 0.13 | D31: 0.65 | F31: 0.34 | I31: 0.6 | J31: -1.63 | K31: -1.04 | L31: -0.46 | M31: 0.88 | N31: -1.39 | Q31: =TRIMMEAN(B31:P31,2/COUNT(B31:P31)) -> -0.16714286
A32: Wyndham Clark | B32: 0.42 | C32: 3.08 | E32: 0.52 | F32: 0.83 | G32: 1.52 | H32: 2.33 | J32: 0.87 | K32: -0.31 | M32: -0.33 | O32: 0.37 | P32: 1.09 | Q32: =TRIMMEAN(B32:P32,2/COUNT(B32:P32)) -> 0.84888889
A33: Eric Cole | C33: 0.53 | D33: 1.28 | E33: 0.94 | F33: 2.04 | H33: -0.15 | I33: 0.33 | J33: 0.18 | K33: -0.01 | M33: 2.25 | N33: -0.31 | O33: -0.7 | P33: 1 | Q33: =TRIMMEAN(B33:P33,2/COUNT(B33:P33)) -> 0.583
A34: Trevor Cone | Q34: =TRIMMEAN(B34:P34,2/COUNT(B34:P34)) -> #DIV/0!
A35: Corey Conners | B35: -0.7 | E35: -0.5 | F35: -1.33 | G35: -0.72 | H35: 0.13 | J35: 0.05 | K35: 0.67 | L35: 0.22 | M35: 0.55 | O35: -0.61 | Q35: =TRIMMEAN(B35:P35,2/COUNT(B35:P35)) -> -0.1975
A36: Pierceson Coody | B36: 1.32 | C36: 2.1 | D36: 1.12 | E36: 0.08 | G36: 0.76 | I36: -0.81 | J36: -1.6 | K36: 1.07 | L36: -0.27 | M36: -0.2 | N36: -4.32 | O36: 0.75 | Q36: =TRIMMEAN(B36:P36,2/COUNT(B36:P36)) -> 0.222
A37: Austin Cook | C37: -2.68 | J37: 0.51 | K37: -0.06 | Q37: =TRIMMEAN(B37:P37,2/COUNT(B37:P37)) -> -0.06
A38: Martin Couvra | C38: -1.06 | D38: -0.68 | E38: -1.44 | H38: -1.07 | I38: -0.06 | J38: 0.66 | K38: -0.61 | Q38: =TRIMMEAN(B38:P38,2/COUNT(B38:P38)) -> -0.696
A39: Quade Cummins | C39: -1.06 | D39: -0.68 | E39: -1.44 | H39: -1.07 | I39: -0.06 | Q39: =TRIMMEAN(B39:P39,2/COUNT(B39:P39)) -> -0.93666667
A40: Joel Dahmen | C40: -0.34 | D40: -0.85 | F40: -2.14 | I40: 0.36 | J40: -0.8 | K40: -1.83 | L40: -0.32 | M40: -0.77 | N40: 1.54 | Q40: =TRIMMEAN(B40:P40,2/COUNT(B40:P40)) -> -0.65
...

Sheet SG ARG
A1: LAST 10 | B1: 46159 | C1: 46166 | D1: 46173 | E1: 46180 | F1: 46187 | G1: 46194 | H1: 46201 | I1: 46208 | J1: 46215 | K1: 46222 | L1: 46229 | M1: 46236 | N1: 46243 | O1: 46250 | P1: 46257 | Q1: SG ARG | S1: Weighted | T1: 1
A2: Ludvig Aberg | B2: 0.58 | D2: -0.11 | E2: -1.37 | G2: 0.54 | H2: 0.05 | J2: -0.03 | K2: 0.24 | O2: 0.02 | P2: 0.3 | Q2: =TRIMMEAN(B2:P2,2/COUNT(B2:P2)) -> 0.14428571
A3: Marcus Armitage | C3: 0.03 | D3: -0.05 | E3: -0.4 | H3: -0.16 | I3: -0.52 | J3: -0.07 | Q3: =TRIMMEAN(B3:P3,2/COUNT(B3:P3)) -> -0.17
A4: Angel Ayora | B4: 0.39 | E4: -0.71 | H4: 0.5 | I4: -0.37 | J4: 0.96 | K4: -0.24 | Q4: =TRIMMEAN(B4:P4,2/COUNT(B4:P4)) -> 0.07
A5: Zach Bauchou | B5: 0.39 | C5: 0.38 | D5: 0.24 | F5: -1.34 | I5: -0.05 | J5: 0.03 | K5: 0.06 | L5: 0.02 | M5: -0.65 | N5: 0.02 | Q5: =TRIMMEAN(B5:P5,2/COUNT(B5:P5)) -> 0.00625
A6: Christiaan Bezuidenhout | B6: 0.47 | C6: -0.03 | D6: 0.88 | F6: 0.09 | I6: 0.18 | J6: 0.08 | K6: -0.18 | L6: 0 | M6: 0 | N6: 0.28 | Q6: =TRIMMEAN(B6:P6,2/COUNT(B6:P6)) -> 0.13375
A7: Daniel Berger | B7: 0.54 | E7: -2.1 | G7: -1.12 | H7: 1.42 | I7: 0.08 | K7: -0.39 | Q7: =TRIMMEAN(B7:P7,2/COUNT(B7:P7)) -> -0.2225
A8: Akshay Bhatia | B8: 0.61 | D8: 0.22 | E8: -0.25 | G8: -0.32 | H8: 0.49 | K8: 0.67 | M8: 0.38 | O8: -0.21 | P8: 0.54 | Q8: =TRIMMEAN(B8:P8,2/COUNT(B8:P8)) -> 0.25428571
A9: Zac Blair | C9: -0.3 | D9: -0.28 | G9: 0.53 | I9: 0.03 | J9: 1.33 | L9: 0.02 | M9: 0.38 | N9: -0.23 | Q9: =TRIMMEAN(B9:P9,2/COUNT(B9:P9)) -> 0.075
A10: Chandler Blanchet | B10: -0.18 | C10: -0.78 | D10: -0.17 | F10: -0.37 | I10: -1.13 | J10: -1.72 | K10: -0.78 | L10: -0.17 | M10: 0.16 | N10: -0.79 | Q10: =TRIMMEAN(B10:P10,2/COUNT(B10:P10)) -> -0.54625
A11: Dan Bradbury | E11: -0.45 | H11: -0.04 | I11: -0.22 | J11: 0.78 | K11: -1.26 | Q11: =TRIMMEAN(B11:P11,2/COUNT(B11:P11)) -> -0.23666667
A12: Keegan Bradley | B12: -0.42 | D12: -0.1 | E12: 1.03 | G12: 0.33 | H12: 1.18 | I12: 0.27 | K12: -0.59 | M12: -0.12 | N12: -0.14 | Q12: =TRIMMEAN(B12:P12,2/COUNT(B12:P12)) -> 0.12142857
A13: Michael Brennan | B13: -0.34 | C13: 0.03 | D13: -0.54 | F13: -0.23 | G13: -0.35 | I13: -0.72 | J13: -0.02 | K13: 0.78 | L13: -1.25 | M13: -0.38 | N13: -0.33 | O13: -0.56 | P13: -0.52 | Q13: =TRIMMEAN(B13:P13,2/COUNT(B13:P13)) -> -0.36
A14: Jacob Bridgeman | B14: -0.66 | E14: 0.12 | F14: 0.02 | G14: -0.15 | H14: -0.12 | I14: -0.6 | K14: 0.36 | M14: 0.69 | O14: -0.8 | P14: 0.58 | Q14: =TRIMMEAN(B14:P14,2/COUNT(B14:P14)) -> -0.05625
A15: Blades Brown | C15: -0.26 | I15: 0.26 | K15: 0.19 | N15: -0.63 | Q15: =TRIMMEAN(B15:P15,2/COUNT(B15:P15)) -> -0.035
A16: Dan Brown | B16: -0.93 | C16: -0.74 | D16: -0.85 | F16: -1.13 | J16: 0.4 | K16: -0.47 | Q16: =TRIMMEAN(B16:P16,2/COUNT(B16:P16)) -> -0.7475
A17: Hayden Buckley | Q17: =TRIMMEAN(B17:P17,2/COUNT(B17:P17)) -> #DIV/0!
A18: Bronson Burgoon | Q18: =TRIMMEAN(B18:P18,2/COUNT(B18:P18)) -> #DIV/0!
A19: Sam Burns | B19: 0.32 | E19: 0.56 | F19: 0.64 | G19: 0.44 | H19: -0.63 | K19: 0.02 | O19: -0.01 | P19: -0.53 | Q19: =TRIMMEAN(B19:P19,2/COUNT(B19:P19)) -> 0.13333333
A20: Brian Campbell | B20: -1.01 | D20: 0.53 | E20: -1.11 | F20: 0.26 | H20: -0.13 | I20: 0.63 | J20: -0.12 | L20: 0.58 | M20: -1.09 | N20: 0.26 | Q20: =TRIMMEAN(B20:P20,2/COUNT(B20:P20)) -> -0.09
A21: Rafael Campos | C21: -3.13 | F21: -1.08 | I21: 0.09 | J21: 0.01 | K21: 0.34 | L21: -0.74 | M21: 1.01 | N21: -0.04 | Q21: =TRIMMEAN(B21:P21,2/COUNT(B21:P21)) -> -0.23666667
A22: Laurie Canter | D22: -0.27 | E22: -0.1 | G22: -0.07 | J22: 0.13 | K22: -0.4 | Q22: =TRIMMEAN(B22:P22,2/COUNT(B22:P22)) -> -0.14666667
A23: Patrick Cantlay | B23: 0.63 | E23: 0.12 | G23: -0.82 | H23: -0.15 | J23: 1.03 | K23: 0.08 | M23: -0.01 | O23: -0.11 | P23: 0.88 | Q23: =TRIMMEAN(B23:P23,2/COUNT(B23:P23)) -> 0.20571429
A24: Frankie Capan III | Q24: =TRIMMEAN(B24:P24,2/COUNT(B24:P24)) -> #DIV/0!
A25: Ricky Castillo | B25: 0.16 | D25: 0 | F25: 0.37 | J25: 0.37 | L25: 0.25 | M25: -0.17 | N25: 0.41 | O25: -0.36 | Q25: =TRIMMEAN(B25:P25,2/COUNT(B25:P25)) -> 0.16333333
A26: Bud Cauley | B26: 0.15 | E26: 0.14 | F26: 0.73 | G26: 0.82 | H26: 1.12 | J26: -1.22 | K26: 0.38 | N26: 0.14 | O26: 0.99 | P26: 0.08 | Q26: =TRIMMEAN(B26:P26,2/COUNT(B26:P26)) -> 0.42875
A27: Eugenio Chacarra | C27: -0.32 | D27: -0.5 | E27: 0.54 | H27: 0.26 | I27: -1.48 | J27: -0.16 | K27: -0.49 | Q27: =TRIMMEAN(B27:P27,2/COUNT(B27:P27)) -> -0.242
A28: Cameron Champ | C28: -0.72 | I28: 0.15 | J28: -0.45 | K28: -0.62 | L28: -0.46 | Q28: =TRIMMEAN(B28:P28,2/COUNT(B28:P28)) -> -0.51
A29: Will Chandler | Q29: =TRIMMEAN(B29:P29,2/COUNT(B29:P29)) -> #DIV/0!
A30: Davis Chatfield | C30: -0.45 | D30: -0.76 | F30: 0.09 | I30: -0.15 | J30: 0.59 | K30: -0.77 | L30: 0.43 | M30: -0.14 | N30: 0.36 | Q30: =TRIMMEAN(B30:P30,2/COUNT(B30:P30)) -> -0.088571429
A31: Luke Clanton | C31: -0.18 | D31: -0.14 | F31: 0.18 | I31: -0.27 | J31: 0.45 | K31: 0.23 | L31: -0.89 | M31: 0.57 | N31: -0.04 | Q31: =TRIMMEAN(B31:P31,2/COUNT(B31:P31)) -> 0.032857143
A32: Wyndham Clark | B32: 0.13 | C32: -0.3 | E32: 1.45 | F32: 1.28 | G32: 0.77 | H32: 1.12 | J32: -0.14 | K32: 0.03 | M32: 0.05 | O32: 0.06 | P32: 0.24 | Q32: =TRIMMEAN(B32:P32,2/COUNT(B32:P32)) -> 0.39333333
A33: Eric Cole | C33: 0.11 | D33: 0.65 | E33: 0.84 | F33: -0.41 | H33: 0.71 | I33: -0.3 | J33: 0.08 | K33: 0.26 | M33: 0.46 | N33: 0.46 | O33: 1.03 | P33: -0.99 | Q33: =TRIMMEAN(B33:P33,2/COUNT(B33:P33)) -> 0.286
A34: Trevor Cone | Q34: =TRIMMEAN(B34:P34,2/COUNT(B34:P34)) -> #DIV/0!
A35: Corey Conners | B35: 0.2 | E35: -0.91 | F35: 0.42 | G35: 0.36 | H35: 1.02 | J35: -0.22 | K35: -0.29 | L35: -0.01 | M35: -0.84 | O35: 0.28 | Q35: =TRIMMEAN(B35:P35,2/COUNT(B35:P35)) -> -0.0125
A36: Pierceson Coody | B36: -1.02 | C36: -1.17 | D36: -0.22 | E36: -1.65 | G36: 0.44 | I36: 0.32 | J36: -0.37 | K36: 0.26 | L36: 0.9 | M36: -1.05 | N36: 0.38 | O36: 0.85 | Q36: =TRIMMEAN(B36:P36,2/COUNT(B36:P36)) -> -0.158
A37: Austin Cook | C37: -0.07 | J37: -0.33 | K37: 0.62 | Q37: =TRIMMEAN(B37:P37,2/COUNT(B37:P37)) -> -0.07
A38: Martin Couvra | C38: 0.25 | D38: 0.36 | E38: 0.44 | H38: 0.1 | I38: -1.2 | J38: -1.05 | K38: -0.75 | Q38: =TRIMMEAN(B38:P38,2/COUNT(B38:P38)) -> -0.218
A39: Quade Cummins | Q39: =TRIMMEAN(B39:P39,2/COUNT(B39:P39)) -> #DIV/0!
A40: Joel Dahmen | C40: -1.18 | D40: 0.61 | F40: -0.12 | I40: 0.12 | J40: 0.21 | K40: 0.45 | L40: -0.4 | M40: -0.2 | N40: -0.24 | Q40: =TRIMMEAN(B40:P40,2/COUNT(B40:P40)) -> -0.025714286
...

Sheet SG APP
A1: LAST 10 | B1: 46159 | C1: 46166 | D1: 46173 | E1: 46180 | F1: 46187 | G1: 46194 | H1: 46201 | I1: 46208 | J1: 46215 | K1: 46222 | L1: 46229 | M1: 46236 | N1: 46243 | O1: 46250 | P1: 46257 | Q1: SG APP | S1: Weighted | T1: 1.75
A2: Ludvig Aberg | B2: 1.37 | D2: 0.14 | E2: 0.52 | G2: 0.37 | H2: 1.06 | J2: 0.5 | K2: 0.88 | O2: 0.07 | P2: -0.35 | Q2: =TRIMMEAN(B2:P2,2/COUNT(B2:P2)) -> 0.50571429
A3: Marcus Armitage | C3: 0.37 | D3: -1.06 | E3: 0.44 | H3: 0.19 | I3: 0.08 | J3: 0.14 | Q3: =TRIMMEAN(B3:P3,2/COUNT(B3:P3)) -> 0.195
A4: Angel Ayora | B4: -0.73 | E4: 0.49 | H4: 0.64 | I4: -1.32 | J4: -0.44 | K4: 1.31 | Q4: =TRIMMEAN(B4:P4,2/COUNT(B4:P4)) -> -0.01
A5: Zach Bauchou | C5: 0.38 | D5: 1.6 | F5: -0.26 | I5: 0.36 | J5: 0.79 | K5: 0.61 | L5: -1.4 | M5: 0.37 | N5: 0.23 | Q5: =TRIMMEAN(B5:P5,2/COUNT(B5:P5)) -> 0.35428571
A6: Christiaan Bezuidenhout | B6: 0.39 | C6: -0.32 | D6: -0.07 | F6: 1.28 | I6: 0.95 | J6: 1.66 | K6: -0.34 | L6: 0.49 | M6: 0.6 | N6: 0.12 | Q6: =TRIMMEAN(B6:P6,2/COUNT(B6:P6)) -> 0.43
A7: Daniel Berger | B7: 0 | E7: 0.61 | G7: 1.06 | H7: 0.65 | I7: -0.32 | K7: -1.12 | Q7: =TRIMMEAN(B7:P7,2/COUNT(B7:P7)) -> 0.235
A8: Akshay Bhatia | B8: -0.51 | D8: 0.26 | E8: -0.64 | G8: 1.35 | H8: 0.54 | K8: -1.35 | M8: 1.81 | O8: -0.17 | P8: 0.56 | Q8: =TRIMMEAN(B8:P8,2/COUNT(B8:P8)) -> 0.19857143
A9: Zac Blair | C9: 0 | D9: 0.47 | G9: 0.64 | I9: 1.28 | J9: 0.46 | L9: 0.28 | M9: 0.58 | N9: 1.31 | Q9: =TRIMMEAN(B9:P9,2/COUNT(B9:P9)) -> 0.61833333
A10: Chandler Blanchet | B10: 0.5 | C10: -0.71 | D10: 0.62 | F10: -0.53 | I10: -0.04 | J10: -0.1 | K10: -0.45 | L10: 0.53 | M10: 0.21 | N10: -2.08 | Q10: =TRIMMEAN(B10:P10,2/COUNT(B10:P10)) -> -0.07375
A11: Dan Bradbury | E11: 0.9 | H11: 0.63 | I11: -0.74 | J11: 0.73 | K11: -1.36 | Q11: =TRIMMEAN(B11:P11,2/COUNT(B11:P11)) -> 0.20666667
A12: Keegan Bradley | B12: -0.16 | D12: 0.75 | E12: 0.64 | G12: 0.64 | H12: 1.34 | I12: 0.02 | K12: 0.74 | M12: 1.42 | N12: 0.67 | Q12: =TRIMMEAN(B12:P12,2/COUNT(B12:P12)) -> 0.68571429
A13: Michael Brennan | B13: -0.74 | C13: -1 | D13: 0.65 | F13: -2.23 | G13: 0.42 | I13: 0.99 | J13: 0.75 | K13: -0.69 | L13: 1.53 | M13: 1.21 | N13: 1.31 | O13: -0.93 | P13: -0.01 | Q13: =TRIMMEAN(B13:P13,2/COUNT(B13:P13)) -> 0.17818182
A14: Jacob Bridgeman | B14: -0.23 | E14: 0.42 | F14: 1.12 | G14: 0.13 | H14: 0.22 | I14: 0.69 | K14: 0.18 | M14: 0.11 | O14: -0.19 | P14: 0.03 | Q14: =TRIMMEAN(B14:P14,2/COUNT(B14:P14)) -> 0.19875
A15: Blades Brown | C15: 1.23 | I15: 0.13 | K15: 1.34 | N15: 0.46 | Q15: =TRIMMEAN(B15:P15,2/COUNT(B15:P15)) -> 0.845
A16: Dan Brown | B16: 0.38 | C16: 0.95 | D16: -0.5 | F16: 2.79 | J16: 2.78 | K16: 0.65 | Q16: =TRIMMEAN(B16:P16,2/COUNT(B16:P16)) -> 1.19
A17: Hayden Buckley | Q17: =TRIMMEAN(B17:P17,2/COUNT(B17:P17)) -> #DIV/0!
A18: Bronson Burgoon | Q18: =TRIMMEAN(B18:P18,2/COUNT(B18:P18)) -> #DIV/0!
A19: Sam Burns | B19: 0.44 | E19: 1.89 | F19: 0.51 | G19: 1.59 | H19: 1.47 | K19: 1.32 | O19: 1.5 | P19: 0.69 | Q19: =TRIMMEAN(B19:P19,2/COUNT(B19:P19)) -> 1.18
A20: Brian Campbell | B20: -0.26 | D20: -0.2 | E20: -0.03 | F20: -0.54 | H20: 0.52 | I20: -1.42 | J20: -1.14 | L20: -0.03 | M20: 2.27 | N20: 0.85 | Q20: =TRIMMEAN(B20:P20,2/COUNT(B20:P20)) -> -0.10375
A21: Rafael Campos | C21: -0.07 | E21: 1.54 | F21: 1.59 | I21: -0.04 | J21: -0.1 | K21: -0.85 | L21: -1.23 | M21: 1.09 | N21: 0.77 | Q21: =TRIMMEAN(B21:P21,2/COUNT(B21:P21)) -> 0.33428571
A22: Laurie Canter | D22: 1.41 | E22: -0.19 | G22: -0.3 | J22: 0.86 | K22: -0.21 | Q22: =TRIMMEAN(B22:P22,2/COUNT(B22:P22)) -> 0.15333333
A23: Patrick Cantlay | B23: 0.58 | G23: 0.3 | H23: 1.46 | J23: -0.65 | K23: 0.09 | M23: 1.69 | O23: 1.32 | P23: 1.76 | Q23: =TRIMMEAN(B23:P23,2/COUNT(B23:P23)) -> 0.90666667
A24: Frankie Capan III | Q24: =TRIMMEAN(B24:P24,2/COUNT(B24:P24)) -> #DIV/0!
A25: Ricky Castillo | B25: -0.35 | D25: 1.15 | F25: -0.17 | J25: -0.78 | L25: -1.37 | M25: 0.42 | N25: 1.4 | O25: -1.21 | Q25: =TRIMMEAN(B25:P25,2/COUNT(B25:P25)) -> -0.15666667
A26: Bud Cauley | B26: 0.44 | E26: 0.49 | F26: 0.39 | G26: 0.34 | H26: 0.72 | J26: -0.2 | K26: 0.23 | N26: -0.52 | O26: -0.36 | P26: -0.9 | Q26: =TRIMMEAN(B26:P26,2/COUNT(B26:P26)) -> 0.10125
A27: Eugenio Chacarra | C27: -0.15 | D27: 0.88 | E27: 1.61 | H27: 1.44 | I27: -0.81 | J27: 1.2 | K27: 0.43 | Q27: =TRIMMEAN(B27:P27,2/COUNT(B27:P27)) -> 0.76
A28: Cameron Champ | C28: -3.84 | I28: -2.34 | J28: -0.16 | K28: -0.72 | L28: -0.98 | Q28: =TRIMMEAN(B28:P28,2/COUNT(B28:P28)) -> -1.3466667
A29: Will Chandler | Q29: =TRIMMEAN(B29:P29,2/COUNT(B29:P29)) -> #DIV/0!
A30: Davis Chatfield | C30: 0.83 | D30: -1.37 | F30: -0.14 | I30: 1.05 | J30: 0.72 | K30: 1.41 | L30: 0.78 | M30: -0.42 | N30: 1.8 | Q30: =TRIMMEAN(B30:P30,2/COUNT(B30:P30)) -> 0.60428571
A31: Luke Clanton | C31: 0.69 | D31: -0.46 | F31: 0.5 | I31: -0.89 | J31: 0.4 | K31: 0.62 | L31: 0.87 | M31: 0.84 | N31: 0.33 | Q31: =TRIMMEAN(B31:P31,2/COUNT(B31:P31)) -> 0.41714286
A32: Wyndham Clark | B32: 0.47 | C32: 0.98 | E32: 2.64 | F32: -0.31 | G32: 0.81 | H32: -0.36 | J32: 0.86 | K32: -0.93 | M32: -2.05 | O32: 1.03 | P32: 1.41 | Q32: =TRIMMEAN(B32:P32,2/COUNT(B32:P32)) -> 0.44
A33: Eric Cole | C33: 0.9 | D33: 0.64 | E33: 1.16 | F33: -2.19 | H33: 0.72 | I33: 0.38 | J33: -1.8 | K33: 0.41 | M33: -1.67 | N33: 0.64 | O33: -0.99 | P33: -0.53 | Q33: =TRIMMEAN(B33:P33,2/COUNT(B33:P33)) -> -0.13
A34: Trevor Cone | Q34: =TRIMMEAN(B34:P34,2/COUNT(B34:P34)) -> #DIV/0!
A35: Corey Conners | B35: 1.41 | E35: -0.65 | F35: -0.55 | G35: 1.4 | H35: 1.11 | J35: 0.21 | K35: 1.84 | L35: -0.57 | M35: 1.2 | O35: -0.44 | Q35: =TRIMMEAN(B35:P35,2/COUNT(B35:P35)) -> 0.47125
A36: Pierceson Coody | B36: -1.14 | C36: -0.97 | D36: 0.04 | E36: -1.21 | G36: 0.36 | I36: 0.73 | J36: -0.39 | K36: 0.44 | L36: -3.41 | M36: -0.45 | N36: -3.25 | O36: -0.21 | Q36: =TRIMMEAN(B36:P36,2/COUNT(B36:P36)) -> -0.678
A37: Austin Cook | C37: -1.52 | J37: 0.38 | K37: 0.16 | Q37: =TRIMMEAN(B37:P37,2/COUNT(B37:P37)) -> 0.16
A38: Martin Couvra | C38: 0.85 | D38: 0.45 | E38: -1.26 | H38: -0.14 | I38: -0.09 | J38: -3.05 | K38: -1.07 | Q38: =TRIMMEAN(B38:P38,2/COUNT(B38:P38)) -> -0.422
A39: Quade Cummins | Q39: =TRIMMEAN(B39:P39,2/COUNT(B39:P39)) -> #DIV/0!
A40: Joel Dahmen | C40: -0.25 | D40: 0.31 | F40: 1.27 | I40: -0.18 | J40: 1.56 | K40: 2.22 | L40: 1.18 | M40: -0.03 | N40: -0.26 | Q40: =TRIMMEAN(B40:P40,2/COUNT(B40:P40)) -> 0.55142857
...

Sheet SG OTT
A1: LAST 10 | B1: 46159 | C1: 46166 | D1: 46173 | E1: 46180 | F1: 46187 | G1: 46194 | H1: 46201 | I1: 46208 | J1: 46215 | K1: 46222 | L1: 46229 | M1: 46236 | N1: 46243 | O1: 46250 | P1: 46257 | Q1: SG OTT | S1: Weighted | T1: 1.4
A2: Ludvig Aberg | B2: 1.11 | D2: 0.88 | E2: 0.41 | G2: 0.81 | H2: -0.18 | J2: 0.32 | K2: 0.75 | O2: 1.35 | P2: -0.66 | Q2: =TRIMMEAN(B2:P2,2/COUNT(B2:P2)) -> 0.58571429
A3: Marcus Armitage | C3: -0.15 | D3: -0.26 | E3: -0.36 | H3: -0.7 | I3: 0.25 | J3: -0.17 | Q3: =TRIMMEAN(B3:P3,2/COUNT(B3:P3)) -> -0.235
A4: Angel Ayora | B4: 1.28 | E4: 0.92 | H4: 0.04 | I4: 0.73 | J4: 0.5 | K4: -0.3 | Q4: =TRIMMEAN(B4:P4,2/COUNT(B4:P4)) -> 0.5475
A5: Zach Bauchou | C5: 0.82 | D5: 0.05 | F5: 0.28 | I5: -0.13 | J5: -0.79 | K5: 0.4 | L5: 0.17 | M5: 0.33 | N5: -0.23 | Q5: =TRIMMEAN(B5:P5,2/COUNT(B5:P5)) -> 0.12428571
A6: Christiaan Bezuidenhout | B6: -0.99 | C6: -1.06 | D6: 0.58 | F6: -0.48 | I6: -0.44 | J6: -0.11 | K6: -0.58 | L6: 0.07 | M6: -0.4 | N6: -0.43 | Q6: =TRIMMEAN(B6:P6,2/COUNT(B6:P6)) -> -0.42
A7: Daniel Berger | B7: 0.09 | E7: 0.71 | G7: -0.16 | H7: 0.07 | I7: 0.27 | K7: 0.96 | Q7: =TRIMMEAN(B7:P7,2/COUNT(B7:P7)) -> 0.285
A8: Akshay Bhatia | B8: -0.8 | D8: -0.34 | E8: -0.33 | G8: 0.56 | H8: 0.46 | K8: -0.18 | M8: -2.72 | O8: -1.74 | P8: -0.71 | Q8: =TRIMMEAN(B8:P8,2/COUNT(B8:P8)) -> -0.52
A9: Zac Blair | C9: -0.68 | D9: -0.04 | G9: -0.87 | I9: -0.63 | J9: -0.33 | L9: -0.1 | M9: -0.66 | N9: -1.43 | Q9: =TRIMMEAN(B9:P9,2/COUNT(B9:P9)) -> -0.545
A10: Chandler Blanchet | B10: 0.32 | C10: -0.1 | D10: 0.08 | F10: -0.01 | I10: -1.41 | J10: 0.43 | K10: -0.08 | L10: 0.95 | M10: 0.41 | N10: 1.05 | Q10: =TRIMMEAN(B10:P10,2/COUNT(B10:P10)) -> 0.25
A11: Dan Bradbury | E11: -0.31 | H11: 0.16 | I11: -0.02 | J11: -0.72 | K11: 0.79 | Q11: =TRIMMEAN(B11:P11,2/COUNT(B11:P11)) -> -0.056666667
A12: Keegan Bradley | B12: 0.62 | D12: -0.55 | E12: 0.16 | G12: 1.04 | H12: -0.21 | I12: 0.3 | K12: -0.19 | M12: 0.46 | N12: 0.72 | Q12: =TRIMMEAN(B12:P12,2/COUNT(B12:P12)) -> 0.26571429
A13: Michael Brennan | B13: 1.13 | C13: 0.88 | D13: 1.09 | F13: 0.15 | G13: 1.41 | I13: 0.65 | J13: 0.41 | K13: 0.81 | L13: 0.39 | M13: -0.75 | N13: 1.21 | O13: 0.66 | P13: 0.94 | Q13: =TRIMMEAN(B13:P13,2/COUNT(B13:P13)) -> 0.75636364
A14: Jacob Bridgeman | B14: 0.49 | E14: 0.68 | F14: -0.07 | G14: -0.01 | H14: 0.7 | I14: 0.23 | K14: 0.11 | M14: -0.18 | O14: -0.01 | P14: 0.06 | Q14: =TRIMMEAN(B14:P14,2/COUNT(B14:P14)) -> 0.185
A15: Blades Brown | C15: 0.49 | I15: 0.73 | K15: 0.25 | N15: -0.21 | Q15: =TRIMMEAN(B15:P15,2/COUNT(B15:P15)) -> 0.37
A16: Dan Brown | B16: 0.07 | C16: 0.37 | D16: 0.2 | F16: -0.79 | J16: -0.49 | K16: 0.66 | Q16: =TRIMMEAN(B16:P16,2/COUNT(B16:P16)) -> 0.0375
A17: Hayden Buckley | Q17: =TRIMMEAN(B17:P17,2/COUNT(B17:P17)) -> #DIV/0!
A18: Bronson Burgoon | Q18: =TRIMMEAN(B18:P18,2/COUNT(B18:P18)) -> #DIV/0!
A19: Sam Burns | B19: -0.2 | E19: 0.37 | F19: 0.25 | G19: 0.48 | H19: 0.82 | K19: 0.63 | O19: -0.81 | P19: -0.26 | Q19: =TRIMMEAN(B19:P19,2/COUNT(B19:P19)) -> 0.21166667
A20: Brian Campbell | B20: -1.51 | D20: -0.24 | E20: 0.76 | F20: -0.99 | H20: -0.59 | I20: -0.87 | J20: -0.09 | L20: 0.03 | M20: -0.49 | N20: 0.13 | Q20: =TRIMMEAN(B20:P20,2/COUNT(B20:P20)) -> -0.38875
A21: Rafael Campos | C21: -0.73 | F21: -2.65 | I21: -0.2 | J21: 0.08 | K21: 0.25 | L21: 0.55 | M21: -0.54 | N21: -0.16 | Q21: =TRIMMEAN(B21:P21,2/COUNT(B21:P21)) -> -0.21666667
A22: Laurie Canter | D22: 0.42 | E22: -0.07 | G22: 0.94 | J22: 0.01 | K22: -0.54 | Q22: =TRIMMEAN(B22:P22,2/COUNT(B22:P22)) -> 0.12
A23: Patrick Cantlay | B23: 0.42 | E23: 0.28 | G23: 1.27 | H23: 0.21 | J23: -0.52 | K23: 0.38 | M23: 0.06 | O23: 0.12 | P23: 0.65 | Q23: =TRIMMEAN(B23:P23,2/COUNT(B23:P23)) -> 0.30285714
A24: Frankie Capan III | Q24: =TRIMMEAN(B24:P24,2/COUNT(B24:P24)) -> #DIV/0!
A25: Ricky Castillo | B25: -1.03 | D25: -0.06 | F25: 0.26 | J25: 0.47 | L25: 0.37 | M25: 0.68 | N25: -0.26 | O25: -0.6 | Q25: =TRIMMEAN(B25:P25,2/COUNT(B25:P25)) -> 0.03
A26: Bud Cauley | B26: 0.05 | E26: 0.81 | F26: 0.59 | G26: 0.23 | H26: 0.74 | J26: -0.6 | K26: -0.76 | N26: 0.97 | O26: 0.72 | P26: -0.44 | Q26: =TRIMMEAN(B26:P26,2/COUNT(B26:P26)) -> 0.2625
A27: Eugenio Chacarra | C27: 0.12 | D27: 0.58 | E27: 0.88 | H27: 0.36 | I27: 1.24 | J27: -0.01 | K27: 0.01 | Q27: =TRIMMEAN(B27:P27,2/COUNT(B27:P27)) -> 0.39
A28: Cameron Champ | C28: -0.87 | I28: -0.36 | J28: 0.85 | K28: 0.39 | L28: 0.52 | Q28: =TRIMMEAN(B28:P28,2/COUNT(B28:P28)) -> 0.18333333
A29: Will Chandler | Q29: =TRIMMEAN(B29:P29,2/COUNT(B29:P29)) -> #DIV/0!
A30: Davis Chatfield | C30: -1.23 | D30: -0.64 | F30: -1.18 | I30: 0.08 | J30: -0.62 | K30: -0.77 | L30: -0.43 | M30: -0.17 | N30: -0.83 | Q30: =TRIMMEAN(B30:P30,2/COUNT(B30:P30)) -> -0.66285714
A31: Luke Clanton | C31: 0.09 | D31: 0.04 | F31: -1.12 | I31: -0.78 | J31: 0.34 | K31: 0.02 | L31: 0.47 | M31: -0.59 | N31: 0.5 | Q31: =TRIMMEAN(B31:P31,2/COUNT(B31:P31)) -> -0.058571429
A32: Wyndham Clark | B32: -1.22 | C32: 0.96 | E32: -0.26 | F32: 0.1 | G32: 0.75 | H32: -0.16 | J32: 0.37 | K32: 0.6 | M32: -0.98 | O32: 0.13 | P32: 0.36 | Q32: =TRIMMEAN(B32:P32,2/COUNT(B32:P32)) -> 0.10111111
A33: Eric Cole | C33: -0.81 | D33: 0.53 | E33: 0.41 | F33: -0.43 | H33: -0.35 | I33: 0.05 | J33: -0.25 | K33: -0.25 | M33: -0.84 | N33: 0.14 | O33: -0.75 | P33: 0.11 | Q33: =TRIMMEAN(B33:P33,2/COUNT(B33:P33)) -> -0.213
A34: Trevor Cone | Q34: =TRIMMEAN(B34:P34,2/COUNT(B34:P34)) -> #DIV/0!
A35: Corey Conners | B35: -0.05 | E35: -0.84 | F35: 0.48 | G35: 0.57 | H35: 0.42 | J35: -0.07 | K35: -0.55 | L35: 0.87 | M35: 0.79 | O35: 0.11 | Q35: =TRIMMEAN(B35:P35,2/COUNT(B35:P35)) -> 0.2125
A36: Pierceson Coody | B36: 0.14 | C36: 1.02 | D36: 0.41 | E36: 0.3 | G36: 0.05 | I36: 0.2 | J36: 0.65 | K36: -0.61 | L36: -1.23 | M36: -0.1 | N36: -0.21 | O36: -0.55 | Q36: =TRIMMEAN(B36:P36,2/COUNT(B36:P36)) -> 0.028
A37: Austin Cook | C37: -0.76 | J37: -0.51 | K37: -0.48 | Q37: =TRIMMEAN(B37:P37,2/COUNT(B37:P37)) -> -0.51
A38: Martin Couvra | C38: 0.2 | D38: -0.1 | E38: -1.09 | H38: 0.31 | I38: 0.19 | J38: -0.27 | K38: -0.17 | Q38: =TRIMMEAN(B38:P38,2/COUNT(B38:P38)) -> -0.03
A39: Quade Cummins | Q39: =TRIMMEAN(B39:P39,2/COUNT(B39:P39)) -> #DIV/0!
A40: Joel Dahmen | C40: -0.76 | D40: 0.28 | F40: -0.5 | I40: -0.1 | J40: 0.02 | K40: 0.41 | L40: 0.3 | M40: 0.69 | N40: -0.36 | Q40: =TRIMMEAN(B40:P40,2/COUNT(B40:P40)) -> 0.0071428571
...

Sheet Current Form
A1: LAST 10 | B1: 46194 | C1: 46201 | D1: 46208 | E1: 46215 | F1: 46222 | G1: 46229 | H1: 46236 | I1: 46243 | J1: 46250 | K1: 46257 | L1: Form | N1: Weighted | O1: 1.5
A2: Ludvig Aberg | B2: 2.11 | C2: -0.07 | E2: 0.29 | F2: 1.91 | J2: 1.34 | K2: 0.35 | L2: =TRIMMEAN(B2:K2,2/COUNT(B2:K2)) -> 0.9725
A3: Marcus Armitage | C3: -1.3 | D3: -0.61 | E3: 1.22 | L3: =TRIMMEAN(B3:K3,2/COUNT(B3:K3)) -> -0.61
A4: Angel Ayora | C4: 1.7 | D4: -2.66 | E4: -0.21 | F4: -0.61 | L4: =TRIMMEAN(B4:K4,2/COUNT(B4:K4)) -> -0.41
A5: Zach Bauchou | D5: -1.05 | E5: 0.29 | F5: 2.25 | G5: 0.26 | H5: -0.81 | I5: 1.93 | L5: =TRIMMEAN(B5:K5,2/COUNT(B5:K5)) -> 0.4175
A6: Christiaan Bezuidenhout | D6: 1.7 | E6: 1.24 | F6: -0.5 | G6: 1.51 | H6: 0.45 | I6: 0.68 | L6: =TRIMMEAN(B6:K6,2/COUNT(B6:K6)) -> 0.97
A7: Daniel Berger | B7: -2.32 | C7: 1.43 | D7: -0.84 | F7: -2.11 | L7: =TRIMMEAN(B7:K7,2/COUNT(B7:K7)) -> -1.475
A8: Akshay Bhatia | B8: 2.11 | C8: 2.93 | F8: -1.11 | H8: -0.31 | J8: -3.41 | K8: 0.6 | L8: =TRIMMEAN(B8:K8,2/COUNT(B8:K8)) -> 0.3225
A9: Zac Blair | B9: 1.36 | D9: 1.95 | E9: 1.99 | G9: 2.01 | H9: 0.2 | I9: -0.1 | L9: =TRIMMEAN(B9:K9,2/COUNT(B9:K9)) -> 1.375
A10: Chandler Blanchet | D10: -4.34 | E10: -3.44 | F10: -0.67 | G10: 1.26 | H10: 1.7 | I10: -3.6 | L10: =TRIMMEAN(B10:K10,2/COUNT(B10:K10)) -> -1.6125
A11: Dan Bradbury | C11: -0.05 | D11: -2.16 | E11: 0.29 | F11: -3.61 | L11: =TRIMMEAN(B11:K11,2/COUNT(B11:K11)) -> -1.105
A12: Keegan Bradley | B12: 1.36 | C12: 1.93 | D12: 0.95 | F12: -1.09 | H12: 1.95 | I12: 0.43 | L12: =TRIMMEAN(B12:K12,2/COUNT(B12:K12)) -> 1.1675
A13: Michael Brennan | B13: 0.86 | D13: 0.7 | E13: -0.03 | F13: 0.41 | G13: 1.26 | H13: 1.95 | I13: 4.43 | J13: -0.41 | K13: 0.85 | L13: =TRIMMEAN(B13:K13,2/COUNT(B13:K13)) -> 0.85714286
A14: Jacob Bridgeman | B14: 1.11 | C14: 0.43 | D14: 0.95 | F14: 1.16 | H14: 1.45 | J14: 0.34 | K14: 1.1 | L14: =TRIMMEAN(B14:K14,2/COUNT(B14:K14)) -> 0.95
A15: Blades Brown | D15: 1.7 | F15: 2 | I15: -3.1 | L15: =TRIMMEAN(B15:K15,2/COUNT(B15:K15)) -> 1.7
A16: Dan Brown | E16: -0.21 | F16: 1.41 | L16: =TRIMMEAN(B16:K16,2/COUNT(B16:K16)) -> #VALUE!
A17: Hayden Buckley | L17: =TRIMMEAN(B17:K17,2/COUNT(B17:K17)) -> #DIV/0!
A18: Bronson Burgoon | L18: =TRIMMEAN(B18:K18,2/COUNT(B18:K18)) -> #DIV/0!
A19: Sam Burns | B19: 3.61 | C19: 2.18 | F19: 2.66 | J19: 1.84 | K19: -0.4 | L19: =TRIMMEAN(B19:K19,2/COUNT(B19:K19)) -> 2.2266667
A20: Brian Campbell | C20: 0.43 | D20: -1.84 | E20: -3.21 | G20: -0.01 | H20: -0.3 | I20: -0.1 | L20: =TRIMMEAN(B20:K20,2/COUNT(B20:K20)) -> -0.5625
A21: Rafael Campos | D21: -1.05 | E21: 1.49 | F21: -0.17 | G21: -2.51 | H21: -1.31 | I21: 1.18 | L21: =TRIMMEAN(B21:K21,2/COUNT(B21:K21)) -> -0.3375
A22: Laurie Canter | B22: 0.86 | E22: 0.22 | F22: -0.84 | L22: =TRIMMEAN(B22:K22,2/COUNT(B22:K22)) -> 0.22
A23: Patrick Cantlay | B23: -0.32 | C23: 1.93 | E23: 0.29 | F23: 1.16 | H23: 2.2 | J23: 1.09 | K23: 2.35 | L23: =TRIMMEAN(B23:K23,2/COUNT(B23:K23)) -> 1.334
A24: Frankie Capan III | L24: =TRIMMEAN(B24:K24,2/COUNT(B24:K24)) -> #DIV/0!
A25: Ricky Castillo | E25: 0.47 | G25: 0.26 | H25: 1.7 | I25: 0.43 | J25: -1.91 | L25: =TRIMMEAN(B25:K25,2/COUNT(B25:K25)) -> 0.38666667
A26: Bud Cauley | B26: 0.36 | C26: 1.93 | E26: -4.71 | F26: 1.41 | I26: 0.18 | J26: 1.09 | K26: -1.4 | L26: =TRIMMEAN(B26:K26,2/COUNT(B26:K26)) -> 0.328
A27: Eugenio Chacarra | C27: 3.7 | D27: -0.66 | E27: -0.03 | F27: 0.66 | L27: =TRIMMEAN(B27:K27,2/COUNT(B27:K27)) -> 0.315
A28: Cameron Champ | D28: -2.84 | E28: 0.49 | F28: -0.25 | G28: -1.51 | L28: =TRIMMEAN(B28:K28,2/COUNT(B28:K28)) -> -0.88
A29: Will Chandler | L29: =TRIMMEAN(B29:K29,2/COUNT(B29:K29)) -> #DIV/0!
A30: Davis Chatfield | D30: 0.7 | E30: 2.24 | F30: 0.75 | G30: 1.76 | H30: -1.31 | I30: 1.18 | L30: =TRIMMEAN(B30:K30,2/COUNT(B30:K30)) -> 1.0975
A31: Luke Clanton | D31: -1.34 | E31: -0.44 | F31: -0.17 | G31: -0.01 | H31: 1.7 | I31: -0.6 | L31: =TRIMMEAN(B31:K31,2/COUNT(B31:K31)) -> -0.305
A32: Wyndham Clark | B32: 3.86 | C32: 2.93 | E32: 1.97 | F32: -0.61 | H32: -3.31 | J32: 1.59 | K32: 3.1 | L32: =TRIMMEAN(B32:K32,2/COUNT(B32:K32)) -> 1.796
A33: Eric Cole | C33: 0.93 | D33: 0.45 | E33: -1.78 | F33: 0.41 | H33: 0.19 | I33: 0.93 | J33: -1.41 | K33: -0.4 | L33: =TRIMMEAN(B33:K33,2/COUNT(B33:K33)) -> 0.028333333
A34: Trevor Cone | L34: =TRIMMEAN(B34:K34,2/COUNT(B34:K34)) -> #DIV/0!
A35: Corey Conners | B35: 1.61 | C35: 2.68 | E35: -0.03 | F35: 1.66 | G35: 0.51 | H35: 1.7 | J35: -0.66 | L35: =TRIMMEAN(B35:K35,2/COUNT(B35:K35)) -> 1.09
A36: Pierceson Coody | B36: 1.61 | D36: 0.45 | E36: -1.71 | F36: 1.16 | G36: -4.01 | H36: -1.81 | I36: -7.39 | J36: 0.84 | L36: =TRIMMEAN(B36:K36,2/COUNT(B36:K36)) -> -0.84666667
A37: Austin Cook | E37: 0.06 | F37: 0.25 | L37: =TRIMMEAN(B37:K37,2/COUNT(B37:K37)) -> #VALUE!
A38: Martin Couvra | C38: -0.8 | D38: -1.16 | E38: -3.71 | F38: -2.61 | L38: =TRIMMEAN(B38:K38,2/COUNT(B38:K38)) -> -1.885
A39: Quade Cummins | L39: =TRIMMEAN(B39:K39,2/COUNT(B39:K39)) -> #DIV/0!
A40: Joel Dahmen | D40: 0.2 | E40: 0.99 | F40: 1.25 | G40: 0.76 | H40: -0.31 | I40: 0.68 | L40: =TRIMMEAN(B40:K40,2/COUNT(B40:K40)) -> 0.6575
...

Sheet PGA Database
A1: Player | B1: SG OTT | C1: Points | D1: Approach | E1: Putting | F1: Around Green | G1: T2Green | H1: Form | I1: History | J1: Tournament | K1: Tour
A2: Ludvig Aberg | B2: ='SG OTT'!Q2 -> 0.58571429 | C2: =Class!Q2 -> 1.2228571 | D2: ='SG APP'!Q2 -> 0.50571429 | E2: ='SG PUTT'!Q2 -> 0.15857143 | F2: ='SG ARG'!Q2 -> 0.14428571 | G2: 0.01 | H2: ='Current Form'!L2 -> 0.9725 | I2: -0.02 | J2: Scottish Open | K2: PGA Tour
A3: Marcus Armitage | B3: ='SG OTT'!Q3 -> -0.235 | C3: =Class!Q3 -> 0.33 | D3: ='SG APP'!Q3 -> 0.195 | E3: ='SG PUTT'!Q3 -> 0.8575 | F3: ='SG ARG'!Q3 -> -0.17 | H3: ='Current Form'!L3 -> -0.61 | J3: Scottish Open | K3: PGA Tour
A4: Angel Ayora | B4: ='SG OTT'!Q4 -> 0.5475 | C4: =Class!Q4 -> 0.295 | D4: ='SG APP'!Q4 -> -0.01 | E4: ='SG PUTT'!Q4 -> -0.925 | F4: ='SG ARG'!Q4 -> 0.07 | H4: ='Current Form'!L4 -> -0.41 | J4: Scottish Open | K4: DP
A5: Zach Bauchou | B5: ='SG OTT'!Q5 -> 0.12428571 | C5: =Class!Q5 -> 0.35714286 | D5: ='SG APP'!Q5 -> 0.35428571 | E5: ='SG PUTT'!Q5 -> 0.26142857 | F5: ='SG ARG'!Q5 -> 0.00625 | H5: ='Current Form'!L5 -> 0.4175 | J5: Wyndham Championship | K5: PGA Tour
A6: Christiaan Bezuidenhout | B6: ='SG OTT'!Q6 -> -0.42 | C6: =Class!Q6 -> 0.3375 | D6: ='SG APP'!Q6 -> 0.43 | E6: ='SG PUTT'!Q6 -> 0.43 | F6: ='SG ARG'!Q6 -> 0.13375 | H6: ='Current Form'!L6 -> 0.97 | J6: Wyndham Championship | K6: PGA Tour
A7: Daniel Berger | B7: ='SG OTT'!Q7 -> 0.285 | C7: =Class!Q7 -> 0.13 | D7: ='SG APP'!Q7 -> 0.235 | E7: ='SG PUTT'!Q7 -> -1.08 | F7: ='SG ARG'!Q7 -> -0.2225 | H7: ='Current Form'!L7 -> -1.475 | J7: Wyndham Championship | K7: PGA Tour
A8: Akshay Bhatia | B8: ='SG OTT'!Q8 -> -0.52 | C8: =Class!Q8 -> 0.46428571 | D8: ='SG APP'!Q8 -> 0.19857143 | E8: ='SG PUTT'!Q8 -> 0.2 | F8: ='SG ARG'!Q8 -> 0.25428571 | G8: -0.02 | H8: ='Current Form'!L8 -> 0.3225 | I8: 0 | J8: Scottish Open | K8: PGA Tour
A9: Zac Blair | B9: ='SG OTT'!Q9 -> -0.545 | C9: =Class!Q9 -> 0.435 | D9: ='SG APP'!Q9 -> 0.61833333 | E9: ='SG PUTT'!Q9 -> 0.405 | F9: ='SG ARG'!Q9 -> 0.075 | H9: ='Current Form'!L9 -> 1.375 | J9: Wyndham Championship | K9: PGA Tour
A10: Chandler Blanchet | B10: ='SG OTT'!Q10 -> 0.25 | C10: =Class!Q10 -> 0.13125 | D10: ='SG APP'!Q10 -> -0.07375 | E10: ='SG PUTT'!Q10 -> -0.53625 | F10: ='SG ARG'!Q10 -> -0.54625 | H10: ='Current Form'!L10 -> -1.6125 | J10: Wyndham Championship | K10: PGA Tour
A11: Dan Bradbury | B11: ='SG OTT'!Q11 -> -0.056666667 | C11: =Class!Q11 -> 0 | D11: ='SG APP'!Q11 -> 0.20666667 | E11: ='SG PUTT'!Q11 -> -1.22 | F11: ='SG ARG'!Q11 -> -0.23666667 | H11: ='Current Form'!L11 -> -1.105 | J11: Scottish Open | K11: DP
A12: Keegan Bradley | B12: ='SG OTT'!Q12 -> 0.26571429 | C12: =Class!Q12 -> 0.50285714 | D12: ='SG APP'!Q12 -> 0.68571429 | E12: ='SG PUTT'!Q12 -> -0.25571429 | F12: ='SG ARG'!Q12 -> 0.12142857 | H12: ='Current Form'!L12 -> 1.1675 | J12: Wyndham Championship | K12: PGA Tour
A13: Michael Brennan | B13: ='SG OTT'!Q13 -> 0.75636364 | C13: =Class!Q13 -> 0.53363636 | D13: ='SG APP'!Q13 -> 0.17818182 | E13: ='SG PUTT'!Q13 -> 0.10181818 | F13: ='SG ARG'!Q13 -> -0.36 | H13: ='Current Form'!L13 -> 0.85714286 | J13: Wyndham Championship | K13: PGA Tour
A14: Jacob Bridgeman | B14: ='SG OTT'!Q14 -> 0.185 | C14: =Class!Q14 -> 0.58375 | D14: ='SG APP'!Q14 -> 0.19875 | E14: ='SG PUTT'!Q14 -> 0.45375 | F14: ='SG ARG'!Q14 -> -0.05625 | G14: 0.02 | H14: ='Current Form'!L14 -> 0.95 | I14: -0.04 | J14: Scottish Open | K14: PGA Tour
A15: Blades Brown | B15: ='SG OTT'!Q15 -> 0.37 | C15: =Class!Q15 -> 0.64 | D15: ='SG APP'!Q15 -> 0.845 | E15: ='SG PUTT'!Q15 -> 0.245 | F15: ='SG ARG'!Q15 -> -0.035 | H15: ='Current Form'!L15 -> 1.7 | J15: Wyndham Championship | K15: PGA Tour
A16: Dan Brown | B16: ='SG OTT'!Q16 -> 0.0375 | C16: =Class!Q16 -> 0.03 | D16: ='SG APP'!Q16 -> 1.19 | E16: ='SG PUTT'!Q16 -> -0.91 | F16: ='SG ARG'!Q16 -> -0.7475 | H16: ='Current Form'!L16 -> #VALUE! | J16: Scottish Open | K16: PGA Tour
A17: Hayden Buckley | B17: ='SG OTT'!Q17 -> #DIV/0! | C17: =Class!Q17 -> #DIV/0! | D17: ='SG APP'!Q17 -> #DIV/0! | E17: ='SG PUTT'!Q17 -> #DIV/0! | F17: ='SG ARG'!Q17 -> #DIV/0! | H17: ='Current Form'!L17 -> #DIV/0! | J17: Scottish Open | K17: PGA Tour
A18: Bronson Burgoon | B18: ='SG OTT'!Q18 -> #DIV/0! | C18: =Class!Q18 -> #DIV/0! | D18: ='SG APP'!Q18 -> #DIV/0! | E18: ='SG PUTT'!Q18 -> #DIV/0! | F18: ='SG ARG'!Q18 -> #DIV/0! | H18: ='Current Form'!L18 -> #DIV/0! | J18: Scottish Open | K18: PGA Tour
A19: Sam Burns | B19: ='SG OTT'!Q19 -> 0.21166667 | C19: =Class!Q19 -> 3.84 | D19: ='SG APP'!Q19 -> 1.18 | E19: ='SG PUTT'!Q19 -> 0.75 | F19: ='SG ARG'!Q19 -> 0.13333333 | G19: 0 | H19: ='Current Form'!L19 -> 2.2266667 | I19: 0.09 | J19: Scottish Open | K19: PGA Tour
A20: Brian Campbell | B20: ='SG OTT'!Q20 -> -0.38875 | C20: =Class!Q20 -> 0 | D20: ='SG APP'!Q20 -> -0.10375 | E20: ='SG PUTT'!Q20 -> -0.735 | F20: ='SG ARG'!Q20 -> -0.09 | H20: ='Current Form'!L20 -> -0.5625 | J20: Wyndham Championship | K20: PGA Tour
A21: Rafael Campos | B21: ='SG OTT'!Q21 -> -0.21666667 | C21: =Class!Q21 -> 0.071666667 | D21: ='SG APP'!Q21 -> 0.33428571 | E21: ='SG PUTT'!Q21 -> -0.53666667 | F21: ='SG ARG'!Q21 -> -0.23666667 | H21: ='Current Form'!L21 -> -0.3375 | J21: Wyndham Championship | K21: PGA Tour
A22: Laurie Canter | B22: ='SG OTT'!Q22 -> 0.12 | C22: =Class!Q22 -> 0.17666667 | D22: ='SG APP'!Q22 -> 0.15333333 | E22: ='SG PUTT'!Q22 -> -0.3 | F22: ='SG ARG'!Q22 -> -0.14666667 | H22: ='Current Form'!L22 -> 0.22 | J22: Scottish Open | K22: DP
A23: Patrick Cantlay | B23: ='SG OTT'!Q23 -> 0.30285714 | C23: =Class!Q23 -> 0.91 | D23: ='SG APP'!Q23 -> 0.90666667 | E23: ='SG PUTT'!Q23 -> 0.038571429 | F23: ='SG ARG'!Q23 -> 0.20571429 | G23: 0.03 | H23: ='Current Form'!L23 -> 1.334 | I23: 0.1 | J23: Scottish Open | K23: PGA Tour
A24: Frankie Capan III | B24: ='SG OTT'!Q24 -> #DIV/0! | C24: =Class!Q24 -> #DIV/0! | D24: ='SG APP'!Q24 -> #DIV/0! | E24: ='SG PUTT'!Q24 -> #DIV/0! | F24: ='SG ARG'!Q24 -> #DIV/0! | H24: ='Current Form'!L24 -> #DIV/0! | J24: Scottish Open | K24: PGA Tour
A25: Ricky Castillo | B25: ='SG OTT'!Q25 -> 0.03 | C25: =Class!Q25 -> 0.20333333 | D25: ='SG APP'!Q25 -> -0.15666667 | E25: ='SG PUTT'!Q25 -> 0.11166667 | F25: ='SG ARG'!Q25 -> 0.16333333 | H25: ='Current Form'!L25 -> 0.38666667 | J25: Wyndham Championship | K25: PGA Tour
A26: Bud Cauley | B26: ='SG OTT'!Q26 -> 0.2625 | C26: =Class!Q26 -> 0.66 | D26: ='SG APP'!Q26 -> 0.10125 | E26: ='SG PUTT'!Q26 -> 0.05875 | F26: ='SG ARG'!Q26 -> 0.42875 | H26: ='Current Form'!L26 -> 0.328 | J26: Wyndham Championship | K26: PGA Tour
A27: Eugenio Chacarra | B27: ='SG OTT'!Q27 -> 0.39 | C27: =Class!Q27 -> 0.934 | D27: ='SG APP'!Q27 -> 0.76 | E27: ='SG PUTT'!Q27 -> 0.334 | F27: ='SG ARG'!Q27 -> -0.242 | H27: ='Current Form'!L27 -> 0.315 | J27: Scottish Open | K27: DP
A28: Cameron Champ | B28: ='SG OTT'!Q28 -> 0.18333333 | C28: =Class!Q28 -> 0 | D28: ='SG APP'!Q28 -> -1.3466667 | E28: ='SG PUTT'!Q28 -> -0.076666667 | F28: ='SG ARG'!Q28 -> -0.51 | H28: ='Current Form'!L28 -> -0.88 | J28: Scottish Open | K28: PGA Tour
A29: Will Chandler | B29: ='SG OTT'!Q29 -> #DIV/0! | C29: =Class!Q29 -> #DIV/0! | D29: ='SG APP'!Q29 -> #DIV/0! | E29: ='SG PUTT'!Q29 -> #DIV/0! | F29: ='SG ARG'!Q29 -> #DIV/0! | H29: ='Current Form'!L29 -> #DIV/0! | J29: Scottish Open | K29: PGA Tour
A30: Davis Chatfield | B30: ='SG OTT'!Q30 -> -0.66285714 | C30: =Class!Q30 -> 0.26 | D30: ='SG APP'!Q30 -> 0.60428571 | E30: ='SG PUTT'!Q30 -> 0.33571429 | F30: ='SG ARG'!Q30 -> -0.088571429 | H30: ='Current Form'!L30 -> 1.0975 | J30: Wyndham Championship | K30: PGA Tour
A31: Luke Clanton | B31: ='SG OTT'!Q31 -> -0.058571429 | C31: =Class!Q31 -> 0.045714286 | D31: ='SG APP'!Q31 -> 0.41714286 | E31: ='SG PUTT'!Q31 -> -0.16714286 | F31: ='SG ARG'!Q31 -> 0.032857143 | H31: ='Current Form'!L31 -> -0.305 | J31: Wyndham Championship | K31: PGA Tour
A32: Wyndham Clark | B32: ='SG OTT'!Q32 -> 0.10111111 | C32: =Class!Q32 -> 4.5522222 | D32: ='SG APP'!Q32 -> 0.44 | E32: ='SG PUTT'!Q32 -> 0.84888889 | F32: ='SG ARG'!Q32 -> 0.39333333 | G32: -0.02 | H32: ='Current Form'!L32 -> 1.796 | I32: 0.05 | J32: Scottish Open | K32: PGA Tour
A33: Eric Cole | B33: ='SG OTT'!Q33 -> -0.213 | C33: =Class!Q33 -> 0.392 | D33: ='SG APP'!Q33 -> -0.13 | E33: ='SG PUTT'!Q33 -> 0.583 | F33: ='SG ARG'!Q33 -> 0.286 | H33: ='Current Form'!L33 -> 0.028333333 | J33: Wyndham Championship | K33: PGA Tour
A34: Trevor Cone | B34: ='SG OTT'!Q34 -> #DIV/0! | C34: =Class!Q34 -> #DIV/0! | D34: ='SG APP'!Q34 -> #DIV/0! | E34: ='SG PUTT'!Q34 -> #DIV/0! | F34: ='SG ARG'!Q34 -> #DIV/0! | H34: ='Current Form'!L34 -> #DIV/0! | J34: Scottish Open | K34: PGA Tour
